Workbook
Name BANCO: Tabla10[BANCO]
Name BANCO: Tabla10[BANCO]
Name Concepto: 'MGZ121'!$J$2:$J$110
Name EMPRESA: INDICE!#REF!
Name ESTADO: METODO[ESTADO]
Name ESTADO: METODO[ESTADO]
Name Familia: INDICE!$H$1:$H$8
Name Gasto: INDICE!$G$2:$G$4
Name Ingreso: INDICE!$F$2:$F$10
Name Inicial: INDICE!$R$2
Name TIPO: INDICE!$C$2:$C$4

Sheet ENE25
B1: ENERO
B2: CONCEPTOS | C2: MGZ121 | D2: MGZ BBVA | E2: MGZ DOLARES | F2: MGZ BAJIO | G2: VICTOR BANAMEX | H2: VICTOR BANORTE | I2: RODRIGO | J2: MOY | K2: NORMA RUTH | L2: VALERIA | M2: MANUEL BANAMEX | N2: ROBERTO | O2: JUAN | P2: NORMA SANCHEZ | Q2: JOSE CARLOS | R2: LUIS ENRIQUE | S2: CESARIA | T2: ALAN | U2: ELVIA | V2: CAJA | W2: CAJA TIGRES | X2: RESERVA | Y2: TOTALES | Z2: ACUMULADO
B3: ENTRADAS
B4: INGRESOS
A5: 11.1 | B5: VENTA PIÑAS | C5: =IFERROR(SUMIFS('MGZ121'!$M$2:'MGZ121'!$M$175,'MGZ121'!$H$2:$H$175,"ENTRADA",'MGZ121'!$J$2:$J$175,$B5),0) -> 6887540 | D5: =IFERROR(SUMIFS('MGZ BBVA'!$M$2:$M$88,'MGZ BBVA'!$H$2:$H$88,"ENTRADA",'MGZ BBVA'!$J$2:$J$88,$B5),0) -> 2018660 | E5: =IFERROR(SUMIFS('MGZ DOLARES'!$M$2:$M$2,'MGZ DOLARES'!$F$2:$F$2,"ENTRADA",'MGZ DOLARES'!$J$2:$J$2,$B5),0) -> 0 | F5: =IFERROR(SUMIFS('MGZ BAJIO'!$M$2:$M$4,'MGZ BAJIO'!$H$2:$H$4,"ENTRADA",'MGZ BAJIO'!$J$2:$J$4,$B5),0) -> 0 | G5: =IFERROR(SUMIFS('VICTOR BANAMEX'!$M$2:$M$65,'VICTOR BANAMEX'!$H$2:$H$65,"ENTRADA",'VICTOR BANAMEX'!$J$2:$J$65,$B5),0) -> 0 | H5: =IFERROR(SUMIFS('VICTOR BANORTE'!$M$2:$M$9,'VICTOR BANORTE'!$H$2:$H$9,"ENTRADA",'VICTOR BANORTE'!$J$2:$J$9,$B5),0) -> 0 | I5: =IFERROR(SUMIFS(RODRIGO!$M$2:$M$2,RODRIGO!$H$2:$H$2,"ENTRADA",RODRIGO!$J$2:$J$2,$B5),0) -> 0 | J5: =IFERROR(SUMIFS(MOY!$M$2:$M$12,MOY!$H$2:$H$12,"ENTRADA",MOY!$J$2:$J$12,$B5),0) -> 0 | K5: =IFERROR(SUMIFS('NORMA RUTH'!$M$2:$M$12,'NORMA RUTH'!$H$2:$H$12,"ENTRADA",'NORMA RUTH'!$J$2:$J$12,$B5),0) -> 70000 | L5: =IFERROR(SUMIFS(VALERIA!$M$2:$M$10,VALERIA!$H$2:$H$10,"ENTRADA",VALERIA!$J$2:$J$10,$B5),0) -> 0 | M5: =IFERROR(SUMIFS('MANUEL BANAMEX'!$M$2:$M$25,'MANUEL BANAMEX'!$H$2:$H$25,"ENTRADA",'MANUEL BANAMEX'!$J$2:$J$25,$B5),0) -> 0 | N5: =IFERROR(SUMIFS(ROBERTO!$M$2:$M$2,ROBERTO!$H$2:$H$2,"ENTRADA",ROBERTO!$J$2:$J$2,$B5),0) -> 0 | O5: =IFERROR(SUMIFS(JUAN!$M$2:$M$11,JUAN!$H$2:$H$11,"ENTRADA",JUAN!$J$2:$J$11,$B5),0) -> 0 | P5: =IFERROR(SUMIFS('NORMA SANCHEZ'!$M$2:$M$14,'NORMA SANCHEZ'!$H$2:$H$14,"ENTRADA",'NORMA SANCHEZ'!$J$2:$J$14,$B5),0) -> 0 | Q5: =IFERROR(SUMIFS('JOSE CARLOS'!$M$2:$M$16,'JOSE CARLOS'!$H$2:$H$16,"ENTRADA",'JOSE CARLOS'!$J$2:$J$16,$B5),0) -> 0 | R5: =IFERROR(SUMIFS('LUIS ENRIQUE '!$M$2:$M$21,'LUIS ENRIQUE '!$H$2:$H$21,"ENTRADA",'LUIS ENRIQUE '!$J$2:$J$21,$B5),0) -> 0 | S5: =IFERROR(SUMIFS(CESARIA!$M$2:$M$15,CESARIA!$H$2:$H$15,"ENTRADA",CESARIA!$J$2:$J$15,$B5),0) -> 0 | T5: =IFERROR(SUMIFS(ALAN!$M$2:$M$14,ALAN!$H$2:$H$14,"ENTRADA",ALAN!$J$2:$J$14,$B5),0) -> 0 | U5: =IFERROR(SUMIFS(ELVIA!$M$2:$M$6,ELVIA!$H$2:$H$6,"ENTRADA",ELVIA!$J$2:$J$6,$B5),0) -> 0 | V5: =IFERROR(SUMIFS(CAJA!$M$2:$M$586,CAJA!$H$2:$H$586,"ENTRADA",CAJA!$J$2:$J$586,$B5),0) -> 1050602 | W5: =IFERROR(SUMIFS('CAJA TIGRES'!$M$2:$M$139,'CAJA TIGRES'!$H$2:$H$139,"ENTRADA",'CAJA TIGRES'!$J$2:$J$139,$B5),0) -> 0 | X5: =IFERROR(SUMIFS(RESERVA!$M$2:$M$2,RESERVA!$H$2:$H$2,"ENTRADA",RESERVA!$J$2:$J$2,$B5),0) -> 0 | Y5: =SUM(C5:X5) -> 10026802 | Z5: =Y5 -> 10026802
A6: 11.2 | B6: VENTA GANADO | C6: =IFERROR(SUMIFS('MGZ121'!$M$2:'MGZ121'!$M$175,'MGZ121'!$H$2:$H$175,"ENTRADA",'MGZ121'!$J$2:$J$175,$B6),0) -> 0 | D6: =IFERROR(SUMIFS('MGZ BBVA'!$M$2:$M$88,'MGZ BBVA'!$H$2:$H$88,"ENTRADA",'MGZ BBVA'!$J$2:$J$88,$B6),0) -> 0 | E6: =IFERROR(SUMIFS('MGZ DOLARES'!$M$2:$M$2,'MGZ DOLARES'!$F$2:$F$2,"ENTRADA",'MGZ DOLARES'!$J$2:$J$2,$B6),0) -> 0 | F6: =IFERROR(SUMIFS('MGZ BAJIO'!$M$2:$M$4,'MGZ BAJIO'!$H$2:$H$4,"ENTRADA",'MGZ BAJIO'!$J$2:$J$4,$B6),0) -> 0 | G6: =IFERROR(SUMIFS('VICTOR BANAMEX'!$M$2:$M$65,'VICTOR BANAMEX'!$H$2:$H$65,"ENTRADA",'VICTOR BANAMEX'!$J$2:$J$65,$B6),0) -> 0 | H6: =IFERROR(SUMIFS('VICTOR BANORTE'!$M$2:$M$9,'VICTOR BANORTE'!$H$2:$H$9,"ENTRADA",'VICTOR BANORTE'!$J$2:$J$9,$B6),0) -> 0 | I6: =IFERROR(SUMIFS(RODRIGO!$M$2:$M$2,RODRIGO!$H$2:$H$2,"ENTRADA",RODRIGO!$J$2:$J$2,$B6),0) -> 0 | J6: =IFERROR(SUMIFS(MOY!$M$2:$M$12,MOY!$H$2:$H$12,"ENTRADA",MOY!$J$2:$J$12,$B6),0) -> 0 | K6: =IFERROR(SUMIFS('NORMA RUTH'!$M$2:$M$12,'NORMA RUTH'!$H$2:$H$12,"ENTRADA",'NORMA RUTH'!$J$2:$J$12,$B6),0) -> 0 | L6: =IFERROR(SUMIFS(VALERIA!$M$2:$M$10,VALERIA!$H$2:$H$10,"ENTRADA",VALERIA!$J$2:$J$10,$B6),0) -> 0 | M6: =IFERROR(SUMIFS('MANUEL BANAMEX'!$M$2:$M$25,'MANUEL BANAMEX'!$H$2:$H$25,"ENTRADA",'MANUEL BANAMEX'!$J$2:$J$25,$B6),0) -> 0 | N6: =IFERROR(SUMIFS(ROBERTO!$M$2:$M$2,ROBERTO!$H$2:$H$2,"ENTRADA",ROBERTO!$J$2:$J$2,$B6),0) -> 0 | O6: =IFERROR(SUMIFS(JUAN!$M$2:$M$11,JUAN!$H$2:$H$11,"ENTRADA",JUAN!$J$2:$J$11,$B6),0) -> 0 | P6: =IFERROR(SUMIFS('NORMA SANCHEZ'!$M$2:$M$14,'NORMA SANCHEZ'!$H$2:$H$14,"ENTRADA",'NORMA SANCHEZ'!$J$2:$J$14,$B6),0) -> 0 | Q6: =IFERROR(SUMIFS('JOSE CARLOS'!$M$2:$M$16,'JOSE CARLOS'!$H$2:$H$16,"ENTRADA",'JOSE CARLOS'!$J$2:$J$16,$B6),0) -> 0 | R6: =IFERROR(SUMIFS('LUIS ENRIQUE '!$M$2:$M$21,'LUIS ENRIQUE '!$H$2:$H$21,"ENTRADA",'LUIS ENRIQUE '!$J$2:$J$21,$B6),0) -> 0 | S6: =IFERROR(SUMIFS(CESARIA!$M$2:$M$15,CESARIA!$H$2:$H$15,"ENTRADA",CESARIA!$J$2:$J$15,$B6),0) -> 0 | T6: =IFERROR(SUMIFS(ALAN!$M$2:$M$14,ALAN!$H$2:$H$14,"ENTRADA",ALAN!$J$2:$J$14,$B6),0) -> 0 | U6: =IFERROR(SUMIFS(ELVIA!$M$2:$M$6,ELVIA!$H$2:$H$6,"ENTRADA",ELVIA!$J$2:$J$6,$B6),0) -> 0 | V6: =IFERROR(SUMIFS(CAJA!$M$2:$M$586,CAJA!$H$2:$H$586,"ENTRADA",CAJA!$J$2:$J$586,$B6),0) -> 185975 | W6: =IFERROR(SUMIFS('CAJA TIGRES'!$M$2:$M$139,'CAJA TIGRES'!$H$2:$H$139,"ENTRADA",'CAJA TIGRES'!$J$2:$J$139,$B6),0) -> 0 | X6: =IFERROR(SUMIFS(RESERVA!$M$2:$M$2,RESERVA!$H$2:$H$2,"ENTRADA",RESERVA!$J$2:$J$2,$B6),0) -> 0 | Y6: =SUM(C6:X6) -> 185975 | Z6: =Y6 -> 185975
A7: 11.3 | B7: OTROS INGRESOS | C7: =IFERROR(SUMIFS('MGZ121'!$M$2:'MGZ121'!$M$175,'MGZ121'!$H$2:$H$175,"ENTRADA",'MGZ121'!$J$2:$J$175,$B7),0) -> 0 | D7: =IFERROR(SUMIFS('MGZ BBVA'!$M$2:$M$88,'MGZ BBVA'!$H$2:$H$88,"ENTRADA",'MGZ BBVA'!$J$2:$J$88,$B7),0) -> 0 | E7: =IFERROR(SUMIFS('MGZ DOLARES'!$M$2:$M$2,'MGZ DOLARES'!$F$2:$F$2,"ENTRADA",'MGZ DOLARES'!$J$2:$J$2,$B7),0) -> 0 | F7: =IFERROR(SUMIFS('MGZ BAJIO'!$M$2:$M$4,'MGZ BAJIO'!$H$2:$H$4,"ENTRADA",'MGZ BAJIO'!$J$2:$J$4,$B7),0) -> 0 | G7: =IFERROR(SUMIFS('VICTOR BANAMEX'!$M$2:$M$65,'VICTOR BANAMEX'!$H$2:$H$65,"ENTRADA",'VICTOR BANAMEX'!$J$2:$J$65,$B7),0) -> 0 | H7: =IFERROR(SUMIFS('VICTOR BANORTE'!$M$2:$M$9,'VICTOR BANORTE'!$H$2:$H$9,"ENTRADA",'VICTOR BANORTE'!$J$2:$J$9,$B7),0) -> 0 | I7: =IFERROR(SUMIFS(RODRIGO!$M$2:$M$2,RODRIGO!$H$2:$H$2,"ENTRADA",RODRIGO!$J$2:$J$2,$B7),0) -> 0 | J7: =IFERROR(SUMIFS(MOY!$M$2:$M$12,MOY!$H$2:$H$12,"ENTRADA",MOY!$J$2:$J$12,$B7),0) -> 0 | K7: =IFERROR(SUMIFS('NORMA RUTH'!$M$2:$M$12,'NORMA RUTH'!$H$2:$H$12,"ENTRADA",'NORMA RUTH'!$J$2:$J$12,$B7),0) -> 0 | L7: =IFERROR(SUMIFS(VALERIA!$M$2:$M$10,VALERIA!$H$2:$H$10,"ENTRADA",VALERIA!$J$2:$J$10,$B7),0) -> 0 | M7: =IFERROR(SUMIFS('MANUEL BANAMEX'!$M$2:$M$25,'MANUEL BANAMEX'!$H$2:$H$25,"ENTRADA",'MANUEL BANAMEX'!$J$2:$J$25,$B7),0) -> 0 | N7: =IFERROR(SUMIFS(ROBERTO!$M$2:$M$2,ROBERTO!$H$2:$H$2,"ENTRADA",ROBERTO!$J$2:$J$2,$B7),0) -> 0 | O7: =IFERROR(SUMIFS(JUAN!$M$2:$M$11,JUAN!$H$2:$H$11,"ENTRADA",JUAN!$J$2:$J$11,$B7),0) -> 0 | P7: =IFERROR(SUMIFS('NORMA SANCHEZ'!$M$2:$M$14,'NORMA SANCHEZ'!$H$2:$H$14,"ENTRADA",'NORMA SANCHEZ'!$J$2:$J$14,$B7),0) -> 0 | Q7: =IFERROR(SUMIFS('JOSE CARLOS'!$M$2:$M$16,'JOSE CARLOS'!$H$2:$H$16,"ENTRADA",'JOSE CARLOS'!$J$2:$J$16,$B7),0) -> 0 | R7: =IFERROR(SUMIFS('LUIS ENRIQUE '!$M$2:$M$21,'LUIS ENRIQUE '!$H$2:$H$21,"ENTRADA",'LUIS ENRIQUE '!$J$2:$J$21,$B7),0) -> 0 | S7: =IFERROR(SUMIFS(CESARIA!$M$2:$M$15,CESARIA!$H$2:$H$15,"ENTRADA",CESARIA!$J$2:$J$15,$B7),0) -> 0 | T7: =IFERROR(SUMIFS(ALAN!$M$2:$M$14,ALAN!$H$2:$H$14,"ENTRADA",ALAN!$J$2:$J$14,$B7),0) -> 0 | U7: =IFERROR(SUMIFS(ELVIA!$M$2:$M$6,ELVIA!$H$2:$H$6,"ENTRADA",ELVIA!$J$2:$J$6,$B7),0) -> 0 | V7: =IFERROR(SUMIFS(CAJA!$M$2:$M$586,CAJA!$H$2:$H$586,"ENTRADA",CAJA!$J$2:$J$586,$B7),0) -> 0 | W7: =IFERROR(SUMIFS('CAJA TIGRES'!$M$2:$M$139,'CAJA TIGRES'!$H$2:$H$139,"ENTRADA",'CAJA TIGRES'!$J$2:$J$139,$B7),0) -> 0 | X7: =IFERROR(SUMIFS(RESERVA!$M$2:$M$2,RESERVA!$H$2:$H$2,"ENTRADA",RESERVA!$J$2:$J$2,$B7),0) -> 0 | Y7: =SUM(C7:X7) -> 0 | Z7: =Y7 -> 0
A8: 11.4 | B8: CABALLOS | C8: =IFERROR(SUMIFS('MGZ121'!$M$2:'MGZ121'!$M$175,'MGZ121'!$H$2:$H$175,"ENTRADA",'MGZ121'!$J$2:$J$175,$B8),0) -> 0 | D8: =IFERROR(SUMIFS('MGZ BBVA'!$M$2:$M$88,'MGZ BBVA'!$H$2:$H$88,"ENTRADA",'MGZ BBVA'!$J$2:$J$88,$B8),0) -> 0 | E8: =IFERROR(SUMIFS('MGZ DOLARES'!$M$2:$M$2,'MGZ DOLARES'!$F$2:$F$2,"ENTRADA",'MGZ DOLARES'!$J$2:$J$2,$B8),0) -> 0 | F8: =IFERROR(SUMIFS('MGZ BAJIO'!$M$2:$M$4,'MGZ BAJIO'!$H$2:$H$4,"ENTRADA",'MGZ BAJIO'!$J$2:$J$4,$B8),0) -> 0 | G8: =IFERROR(SUMIFS('VICTOR BANAMEX'!$M$2:$M$65,'VICTOR BANAMEX'!$H$2:$H$65,"ENTRADA",'VICTOR BANAMEX'!$J$2:$J$65,$B8),0) -> 0 | H8: =IFERROR(SUMIFS('VICTOR BANORTE'!$M$2:$M$9,'VICTOR BANORTE'!$H$2:$H$9,"ENTRADA",'VICTOR BANORTE'!$J$2:$J$9,$B8),0) -> 0 | I8: =IFERROR(SUMIFS(RODRIGO!$M$2:$M$2,RODRIGO!$H$2:$H$2,"ENTRADA",RODRIGO!$J$2:$J$2,$B8),0) -> 0 | J8: =IFERROR(SUMIFS(MOY!$M$2:$M$12,MOY!$H$2:$H$12,"ENTRADA",MOY!$J$2:$J$12,$B8),0) -> 0 | K8: =IFERROR(SUMIFS('NORMA RUTH'!$M$2:$M$12,'NORMA RUTH'!$H$2:$H$12,"ENTRADA",'NORMA RUTH'!$J$2:$J$12,$B8),0) -> 0 | L8: =IFERROR(SUMIFS(VALERIA!$M$2:$M$10,VALERIA!$H$2:$H$10,"ENTRADA",VALERIA!$J$2:$J$10,$B8),0) -> 0 | M8: =IFERROR(SUMIFS('MANUEL BANAMEX'!$M$2:$M$25,'MANUEL BANAMEX'!$H$2:$H$25,"ENTRADA",'MANUEL BANAMEX'!$J$2:$J$25,$B8),0) -> 0 | N8: =IFERROR(SUMIFS(ROBERTO!$M$2:$M$2,ROBERTO!$H$2:$H$2,"ENTRADA",ROBERTO!$J$2:$J$2,$B8),0) -> 0 | O8: =IFERROR(SUMIFS(JUAN!$M$2:$M$11,JUAN!$H$2:$H$11,"ENTRADA",JUAN!$J$2:$J$11,$B8),0) -> 0 | P8: =IFERROR(SUMIFS('NORMA SANCHEZ'!$M$2:$M$14,'NORMA SANCHEZ'!$H$2:$H$14,"ENTRADA",'NORMA SANCHEZ'!$J$2:$J$14,$B8),0) -> 0 | Q8: =IFERROR(SUMIFS('JOSE CARLOS'!$M$2:$M$16,'JOSE CARLOS'!$H$2:$H$16,"ENTRADA",'JOSE CARLOS'!$J$2:$J$16,$B8),0) -> 0 | R8: =IFERROR(SUMIFS('LUIS ENRIQUE '!$M$2:$M$21,'LUIS ENRIQUE '!$H$2:$H$21,"ENTRADA",'LUIS ENRIQUE '!$J$2:$J$21,$B8),0) -> 0 | S8: =IFERROR(SUMIFS(CESARIA!$M$2:$M$15,CESARIA!$H$2:$H$15,"ENTRADA",CESARIA!$J$2:$J$15,$B8),0) -> 0 | T8: =IFERROR(SUMIFS(ALAN!$M$2:$M$14,ALAN!$H$2:$H$14,"ENTRADA",ALAN!$J$2:$J$14,$B8),0) -> 0 | U8: =IFERROR(SUMIFS(ELVIA!$M$2:$M$6,ELVIA!$H$2:$H$6,"ENTRADA",ELVIA!$J$2:$J$6,$B8),0) -> 0 | V8: =IFERROR(SUMIFS(CAJA!$M$2:$M$586,CAJA!$H$2:$H$586,"ENTRADA",CAJA!$J$2:$J$586,$B8),0) -> 0 | W8: =IFERROR(SUMIFS('CAJA TIGRES'!$M$2:$M$139,'CAJA TIGRES'!$H$2:$H$139,"ENTRADA",'CAJA TIGRES'!$J$2:$J$139,$B8),0) -> 0 | X8: =IFERROR(SUMIFS(RESERVA!$M$2:$M$2,RESERVA!$H$2:$H$2,"ENTRADA",RESERVA!$J$2:$J$2,$B8),0) -> 0 | Y8: =SUM(C8:X8) -> 0 | Z8: =Y8 -> 0
A9: 11.5 | B9: PRODUCTOS FINANCIEROS | C9: =IFERROR(SUMIFS('MGZ121'!$M$2:'MGZ121'!$M$175,'MGZ121'!$H$2:$H$175,"ENTRADA",'MGZ121'!$J$2:$J$175,$B9),0) -> 0.02 | D9: =IFERROR(SUMIFS('MGZ BBVA'!$M$2:$M$88,'MGZ BBVA'!$H$2:$H$88,"ENTRADA",'MGZ BBVA'!$J$2:$J$88,$B9),0) -> 0.97 | E9: =IFERROR(SUMIFS('MGZ DOLARES'!$M$2:$M$2,'MGZ DOLARES'!$F$2:$F$2,"ENTRADA",'MGZ DOLARES'!$J$2:$J$2,$B9),0) -> 0 | F9: =IFERROR(SUMIFS('MGZ BAJIO'!$M$2:$M$4,'MGZ BAJIO'!$H$2:$H$4,"ENTRADA",'MGZ BAJIO'!$J$2:$J$4,$B9),0) -> 0 | G9: =IFERROR(SUMIFS('VICTOR BANAMEX'!$M$2:$M$65,'VICTOR BANAMEX'!$H$2:$H$65,"ENTRADA",'VICTOR BANAMEX'!$J$2:$J$65,$B9),0) -> 0 | H9: =IFERROR(SUMIFS('VICTOR BANORTE'!$M$2:$M$9,'VICTOR BANORTE'!$H$2:$H$9,"ENTRADA",'VICTOR BANORTE'!$J$2:$J$9,$B9),0) -> 0 | I9: =IFERROR(SUMIFS(RODRIGO!$M$2:$M$2,RODRIGO!$H$2:$H$2,"ENTRADA",RODRIGO!$J$2:$J$2,$B9),0) -> 0 | J9: =IFERROR(SUMIFS(MOY!$M$2:$M$12,MOY!$H$2:$H$12,"ENTRADA",MOY!$J$2:$J$12,$B9),0) -> 0 | K9: =IFERROR(SUMIFS('NORMA RUTH'!$M$2:$M$12,'NORMA RUTH'!$H$2:$H$12,"ENTRADA",'NORMA RUTH'!$J$2:$J$12,$B9),0) -> 0 | L9: =IFERROR(SUMIFS(VALERIA!$M$2:$M$10,VALERIA!$H$2:$H$10,"ENTRADA",VALERIA!$J$2:$J$10,$B9),0) -> 0 | M9: =IFERROR(SUMIFS('MANUEL BANAMEX'!$M$2:$M$25,'MANUEL BANAMEX'!$H$2:$H$25,"ENTRADA",'MANUEL BANAMEX'!$J$2:$J$25,$B9),0) -> 0 | N9: =IFERROR(SUMIFS(ROBERTO!$M$2:$M$2,ROBERTO!$H$2:$H$2,"ENTRADA",ROBERTO!$J$2:$J$2,$B9),0) -> 0 | O9: =IFERROR(SUMIFS(JUAN!$M$2:$M$11,JUAN!$H$2:$H$11,"ENTRADA",JUAN!$J$2:$J$11,$B9),0) -> 0 | P9: =IFERROR(SUMIFS('NORMA SANCHEZ'!$M$2:$M$14,'NORMA SANCHEZ'!$H$2:$H$14,"ENTRADA",'NORMA SANCHEZ'!$J$2:$J$14,$B9),0) -> 0 | Q9: =IFERROR(SUMIFS('JOSE CARLOS'!$M$2:$M$16,'JOSE CARLOS'!$H$2:$H$16,"ENTRADA",'JOSE CARLOS'!$J$2:$J$16,$B9),0) -> 0 | R9: =IFERROR(SUMIFS('LUIS ENRIQUE '!$M$2:$M$21,'LUIS ENRIQUE '!$H$2:$H$21,"ENTRADA",'LUIS ENRIQUE '!$J$2:$J$21,$B9),0) -> 0 | S9: =IFERROR(SUMIFS(CESARIA!$M$2:$M$15,CESARIA!$H$2:$H$15,"ENTRADA",CESARIA!$J$2:$J$15,$B9),0) -> 0 | T9: =IFERROR(SUMIFS(ALAN!$M$2:$M$14,ALAN!$H$2:$H$14,"ENTRADA",ALAN!$J$2:$J$14,$B9),0) -> 0 | U9: =IFERROR(SUMIFS(ELVIA!$M$2:$M$6,ELVIA!$H$2:$H$6,"ENTRADA",ELVIA!$J$2:$J$6,$B9),0) -> 0 | V9: =IFERROR(SUMIFS(CAJA!$M$2:$M$586,CAJA!$H$2:$H$586,"ENTRADA",CAJA!$J$2:$J$586,$B9),0) -> 0 | W9: =IFERROR(SUMIFS('CAJA TIGRES'!$M$2:$M$139,'CAJA TIGRES'!$H$2:$H$139,"ENTRADA",'CAJA TIGRES'!$J$2:$J$139,$B9),0) -> 0 | X9: =IFERROR(SUMIFS(RESERVA!$M$2:$M$2,RESERVA!$H$2:$H$2,"ENTRADA",RESERVA!$J$2:$J$2,$B9),0) -> 0 | Y9: =SUM(C9:X9) -> 0.99 | Z9: =Y9 -> 0.99
A10: 11.6 | B10: REMESAS | C10: =IFERROR(SUMIFS('MGZ121'!$M$2:'MGZ121'!$M$175,'MGZ121'!$H$2:$H$175,"ENTRADA",'MGZ121'!$J$2:$J$175,$B10),0) -> 0 | D10: =IFERROR(SUMIFS('MGZ BBVA'!$M$2:$M$88,'MGZ BBVA'!$H$2:$H$88,"ENTRADA",'MGZ BBVA'!$J$2:$J$88,$B10),0) -> 0 | E10: =IFERROR(SUMIFS('MGZ DOLARES'!$M$2:$M$2,'MGZ DOLARES'!$F$2:$F$2,"ENTRADA",'MGZ DOLARES'!$J$2:$J$2,$B10),0) -> 0 | F10: =IFERROR(SUMIFS('MGZ BAJIO'!$M$2:$M$4,'MGZ BAJIO'!$H$2:$H$4,"ENTRADA",'MGZ BAJIO'!$J$2:$J$4,$B10),0) -> 0 | G10: =IFERROR(SUMIFS('VICTOR BANAMEX'!$M$2:$M$65,'VICTOR BANAMEX'!$H$2:$H$65,"ENTRADA",'VICTOR BANAMEX'!$J$2:$J$65,$B10),0) -> 0 | H10: =IFERROR(SUMIFS('VICTOR BANORTE'!$M$2:$M$9,'VICTOR BANORTE'!$H$2:$H$9,"ENTRADA",'VICTOR BANORTE'!$J$2:$J$9,$B10),0) -> 0 | I10: =IFERROR(SUMIFS(RODRIGO!$M$2:$M$2,RODRIGO!$H$2:$H$2,"ENTRADA",RODRIGO!$J$2:$J$2,$B10),0) -> 0 | J10: =IFERROR(SUMIFS(MOY!$M$2:$M$12,MOY!$H$2:$H$12,"ENTRADA",MOY!$J$2:$J$12,$B10),0) -> 0 | K10: =IFERROR(SUMIFS('NORMA RUTH'!$M$2:$M$12,'NORMA RUTH'!$H$2:$H$12,"ENTRADA",'NORMA RUTH'!$J$2:$J$12,$B10),0) -> 0 | L10: =IFERROR(SUMIFS(VALERIA!$M$2:$M$10,VALERIA!$H$2:$H$10,"ENTRADA",VALERIA!$J$2:$J$10,$B10),0) -> 0 | M10: =IFERROR(SUMIFS('MANUEL BANAMEX'!$M$2:$M$25,'MANUEL BANAMEX'!$H$2:$H$25,"ENTRADA",'MANUEL BANAMEX'!$J$2:$J$25,$B10),0) -> 0 | N10: =IFERROR(SUMIFS(ROBERTO!$M$2:$M$2,ROBERTO!$H$2:$H$2,"ENTRADA",ROBERTO!$J$2:$J$2,$B10),0) -> 0 | O10: =IFERROR(SUMIFS(JUAN!$M$2:$M$11,JUAN!$H$2:$H$11,"ENTRADA",JUAN!$J$2:$J$11,$B10),0) -> 0 | P10: =IFERROR(SUMIFS('NORMA SANCHEZ'!$M$2:$M$14,'NORMA SANCHEZ'!$H$2:$H$14,"ENTRADA",'NORMA SANCHEZ'!$J$2:$J$14,$B10),0) -> 0 | Q10: =IFERROR(SUMIFS('JOSE CARLOS'!$M$2:$M$16,'JOSE CARLOS'!$H$2:$H$16,"ENTRADA",'JOSE CARLOS'!$J$2:$J$16,$B10),0) -> 0 | R10: =IFERROR(SUMIFS('LUIS ENRIQUE '!$M$2:$M$21,'LUIS ENRIQUE '!$H$2:$H$21,"ENTRADA",'LUIS ENRIQUE '!$J$2:$J$21,$B10),0) -> 0 | S10: =IFERROR(SUMIFS(CESARIA!$M$2:$M$15,CESARIA!$H$2:$H$15,"ENTRADA",CESARIA!$J$2:$J$15,$B10),0) -> 0 | T10: =IFERROR(SUMIFS(ALAN!$M$2:$M$14,ALAN!$H$2:$H$14,"ENTRADA",ALAN!$J$2:$J$14,$B10),0) -> 0 | U10: =IFERROR(SUMIFS(ELVIA!$M$2:$M$6,ELVIA!$H$2:$H$6,"ENTRADA",ELVIA!$J$2:$J$6,$B10),0) -> 0 | V10: =IFERROR(SUMIFS(CAJA!$M$2:$M$586,CAJA!$H$2:$H$586,"ENTRADA",CAJA!$J$2:$J$586,$B10),0) -> 0 | W10: =IFERROR(SUMIFS('CAJA TIGRES'!$M$2:$M$139,'CAJA TIGRES'!$H$2:$H$139,"ENTRADA",'CAJA TIGRES'!$J$2:$J$139,$B10),0) -> 0 | X10: =IFERROR(SUMIFS(RESERVA!$M$2:$M$2,RESERVA!$H$2:$H$2,"ENTRADA",RESERVA!$J$2:$J$2,$B10),0) -> 0 | Y10: =SUM(C10:X10) -> 0 | Z10: =Y10 -> 0
A11: 11.7 | B11: REEMBOLSO | C11: =IFERROR(SUMIFS('MGZ121'!$M$2:'MGZ121'!$M$175,'MGZ121'!$H$2:$H$175,"ENTRADA",'MGZ121'!$J$2:$J$175,$B11),0) -> 0 | D11: =IFERROR(SUMIFS('MGZ BBVA'!$M$2:$M$88,'MGZ BBVA'!$H$2:$H$88,"ENTRADA",'MGZ BBVA'!$J$2:$J$88,$B11),0) -> 0 | E11: =IFERROR(SUMIFS('MGZ DOLARES'!$M$2:$M$2,'MGZ DOLARES'!$F$2:$F$2,"ENTRADA",'MGZ DOLARES'!$J$2:$J$2,$B11),0) -> 0 | F11: =IFERROR(SUMIFS('MGZ BAJIO'!$M$2:$M$4,'MGZ BAJIO'!$H$2:$H$4,"ENTRADA",'MGZ BAJIO'!$J$2:$J$4,$B11),0) -> 0 | G11: =IFERROR(SUMIFS('VICTOR BANAMEX'!$M$2:$M$65,'VICTOR BANAMEX'!$H$2:$H$65,"ENTRADA",'VICTOR BANAMEX'!$J$2:$J$65,$B11),0) -> 0 | H11: =IFERROR(SUMIFS('VICTOR BANORTE'!$M$2:$M$9,'VICTOR BANORTE'!$H$2:$H$9,"ENTRADA",'VICTOR BANORTE'!$J$2:$J$9,$B11),0) -> 0 | I11: =IFERROR(SUMIFS(RODRIGO!$M$2:$M$2,RODRIGO!$H$2:$H$2,"ENTRADA",RODRIGO!$J$2:$J$2,$B11),0) -> 0 | J11: =IFERROR(SUMIFS(MOY!$M$2:$M$12,MOY!$H$2:$H$12,"ENTRADA",MOY!$J$2:$J$12,$B11),0) -> 0 | K11: =IFERROR(SUMIFS('NORMA RUTH'!$M$2:$M$12,'NORMA RUTH'!$H$2:$H$12,"ENTRADA",'NORMA RUTH'!$J$2:$J$12,$B11),0) -> 0 | L11: =IFERROR(SUMIFS(VALERIA!$M$2:$M$10,VALERIA!$H$2:$H$10,"ENTRADA",VALERIA!$J$2:$J$10,$B11),0) -> 0 | M11: =IFERROR(SUMIFS('MANUEL BANAMEX'!$M$2:$M$25,'MANUEL BANAMEX'!$H$2:$H$25,"ENTRADA",'MANUEL BANAMEX'!$J$2:$J$25,$B11),0) -> 0 | N11: =IFERROR(SUMIFS(ROBERTO!$M$2:$M$2,ROBERTO!$H$2:$H$2,"ENTRADA",ROBERTO!$J$2:$J$2,$B11),0) -> 0 | O11: =IFERROR(SUMIFS(JUAN!$M$2:$M$11,JUAN!$H$2:$H$11,"ENTRADA",JUAN!$J$2:$J$11,$B11),0) -> 0 | P11: =IFERROR(SUMIFS('NORMA SANCHEZ'!$M$2:$M$14,'NORMA SANCHEZ'!$H$2:$H$14,"ENTRADA",'NORMA SANCHEZ'!$J$2:$J$14,$B11),0) -> 0 | Q11: =IFERROR(SUMIFS('JOSE CARLOS'!$M$2:$M$16,'JOSE CARLOS'!$H$2:$H$16,"ENTRADA",'JOSE CARLOS'!$J$2:$J$16,$B11),0) -> 0 | R11: =IFERROR(SUMIFS('LUIS ENRIQUE '!$M$2:$M$21,'LUIS ENRIQUE '!$H$2:$H$21,"ENTRADA",'LUIS ENRIQUE '!$J$2:$J$21,$B11),0) -> 0 | S11: =IFERROR(SUMIFS(CESARIA!$M$2:$M$15,CESARIA!$H$2:$H$15,"ENTRADA",CESARIA!$J$2:$J$15,$B11),0) -> 0 | T11: =IFERROR(SUMIFS(ALAN!$M$2:$M$14,ALAN!$H$2:$H$14,"ENTRADA",ALAN!$J$2:$J$14,$B11),0) -> 0 | U11: =IFERROR(SUMIFS(ELVIA!$M$2:$M$6,ELVIA!$H$2:$H$6,"ENTRADA",ELVIA!$J$2:$J$6,$B11),0) -> 0 | V11: =IFERROR(SUMIFS(CAJA!$M$2:$M$586,CAJA!$H$2:$H$586,"ENTRADA",CAJA!$J$2:$J$586,$B11),0) -> 0 | W11: =IFERROR(SUMIFS('CAJA TIGRES'!$M$2:$M$139,'CAJA TIGRES'!$H$2:$H$139,"ENTRADA",'CAJA TIGRES'!$J$2:$J$139,$B11),0) -> 0 | X11: =IFERROR(SUMIFS(RESERVA!$M$2:$M$2,RESERVA!$H$2:$H$2,"ENTRADA",RESERVA!$J$2:$J$2,$B11),0) -> 0 | Y11: =SUM(C11:X11) -> 0 | Z11: =Y11 -> 0
A12: 11.8 | B12: VENTA EXTERNA | C12: =IFERROR(SUMIFS('MGZ121'!$M$2:'MGZ121'!$M$175,'MGZ121'!$H$2:$H$175,"ENTRADA",'MGZ121'!$J$2:$J$175,$B12),0) -> 0 | D12: =IFERROR(SUMIFS('MGZ BBVA'!$M$2:$M$88,'MGZ BBVA'!$H$2:$H$88,"ENTRADA",'MGZ BBVA'!$J$2:$J$88,$B12),0) -> 0 | E12: =IFERROR(SUMIFS('MGZ DOLARES'!$M$2:$M$2,'MGZ DOLARES'!$F$2:$F$2,"ENTRADA",'MGZ DOLARES'!$J$2:$J$2,$B12),0) -> 0 | F12: =IFERROR(SUMIFS('MGZ BAJIO'!$M$2:$M$4,'MGZ BAJIO'!$H$2:$H$4,"ENTRADA",'MGZ BAJIO'!$J$2:$J$4,$B12),0) -> 0 | G12: =IFERROR(SUMIFS('VICTOR BANAMEX'!$M$2:$M$65,'VICTOR BANAMEX'!$H$2:$H$65,"ENTRADA",'VICTOR BANAMEX'!$J$2:$J$65,$B12),0) -> 0 | H12: =IFERROR(SUMIFS('VICTOR BANORTE'!$M$2:$M$9,'VICTOR BANORTE'!$H$2:$H$9,"ENTRADA",'VICTOR BANORTE'!$J$2:$J$9,$B12),0) -> 0 | I12: =IFERROR(SUMIFS(RODRIGO!$M$2:$M$2,RODRIGO!$H$2:$H$2,"ENTRADA",RODRIGO!$J$2:$J$2,$B12),0) -> 0 | J12: =IFERROR(SUMIFS(MOY!$M$2:$M$12,MOY!$H$2:$H$12,"ENTRADA",MOY!$J$2:$J$12,$B12),0) -> 0 | K12: =IFERROR(SUMIFS('NORMA RUTH'!$M$2:$M$12,'NORMA RUTH'!$H$2:$H$12,"ENTRADA",'NORMA RUTH'!$J$2:$J$12,$B12),0) -> 0 | L12: =IFERROR(SUMIFS(VALERIA!$M$2:$M$10,VALERIA!$H$2:$H$10,"ENTRADA",VALERIA!$J$2:$J$10,$B12),0) -> 0 | M12: =IFERROR(SUMIFS('MANUEL BANAMEX'!$M$2:$M$25,'MANUEL BANAMEX'!$H$2:$H$25,"ENTRADA",'MANUEL BANAMEX'!$J$2:$J$25,$B12),0) -> 8000 | N12: =IFERROR(SUMIFS(ROBERTO!$M$2:$M$2,ROBERTO!$H$2:$H$2,"ENTRADA",ROBERTO!$J$2:$J$2,$B12),0) -> 0 | O12: =IFERROR(SUMIFS(JUAN!$M$2:$M$11,JUAN!$H$2:$H$11,"ENTRADA",JUAN!$J$2:$J$11,$B12),0) -> 0 | P12: =IFERROR(SUMIFS('NORMA SANCHEZ'!$M$2:$M$14,'NORMA SANCHEZ'!$H$2:$H$14,"ENTRADA",'NORMA SANCHEZ'!$J$2:$J$14,$B12),0) -> 8000 | Q12: =IFERROR(SUMIFS('JOSE CARLOS'!$M$2:$M$16,'JOSE CARLOS'!$H$2:$H$16,"ENTRADA",'JOSE CARLOS'!$J$2:$J$16,$B12),0) -> 0 | R12: =IFERROR(SUMIFS('LUIS ENRIQUE '!$M$2:$M$21,'LUIS ENRIQUE '!$H$2:$H$21,"ENTRADA",'LUIS ENRIQUE '!$J$2:$J$21,$B12),0) -> 0 | S12: =IFERROR(SUMIFS(CESARIA!$M$2:$M$15,CESARIA!$H$2:$H$15,"ENTRADA",CESARIA!$J$2:$J$15,$B12),0) -> 0 | T12: =IFERROR(SUMIFS(ALAN!$M$2:$M$14,ALAN!$H$2:$H$14,"ENTRADA",ALAN!$J$2:$J$14,$B12),0) -> 0 | U12: =IFERROR(SUMIFS(ELVIA!$M$2:$M$6,ELVIA!$H$2:$H$6,"ENTRADA",ELVIA!$J$2:$J$6,$B12),0) -> 0 | V12: =IFERROR(SUMIFS(CAJA!$M$2:$M$586,CAJA!$H$2:$H$586,"ENTRADA",CAJA!$J$2:$J$586,$B12),0) -> 0 | W12: =IFERROR(SUMIFS('CAJA TIGRES'!$M$2:$M$139,'CAJA TIGRES'!$H$2:$H$139,"ENTRADA",'CAJA TIGRES'!$J$2:$J$139,$B12),0) -> 0 | X12: =IFERROR(SUMIFS(RESERVA!$M$2:$M$2,RESERVA!$H$2:$H$2,"ENTRADA",RESERVA!$J$2:$J$2,$B12),0) -> 0 | Y12: =SUM(C12:X12) -> 16000 | Z12: =Y12 -> 16000
B13: VENTA POMELERO | C13: =IFERROR(SUMIFS('MGZ121'!$M$2:'MGZ121'!$M$175,'MGZ121'!$H$2:$H$175,"ENTRADA",'MGZ121'!$J$2:$J$175,$B13),0) -> 0 | D13: =IFERROR(SUMIFS('MGZ BBVA'!$M$2:$M$88,'MGZ BBVA'!$H$2:$H$88,"ENTRADA",'MGZ BBVA'!$J$2:$J$88,$B13),0) -> 0 | E13: =IFERROR(SUMIFS('MGZ DOLARES'!$M$2:$M$2,'MGZ DOLARES'!$F$2:$F$2,"ENTRADA",'MGZ DOLARES'!$J$2:$J$2,$B13),0) -> 0 | F13: =IFERROR(SUMIFS('MGZ BAJIO'!$M$2:$M$4,'MGZ BAJIO'!$H$2:$H$4,"ENTRADA",'MGZ BAJIO'!$J$2:$J$4,$B13),0) -> 0 | G13: =IFERROR(SUMIFS('VICTOR BANAMEX'!$M$2:$M$65,'VICTOR BANAMEX'!$H$2:$H$65,"ENTRADA",'VICTOR BANAMEX'!$J$2:$J$65,$B13),0) -> 0 | H13: =IFERROR(SUMIFS('VICTOR BANORTE'!$M$2:$M$9,'VICTOR BANORTE'!$H$2:$H$9,"ENTRADA",'VICTOR BANORTE'!$J$2:$J$9,$B13),0) -> 0 | I13: =IFERROR(SUMIFS(RODRIGO!$M$2:$M$2,RODRIGO!$H$2:$H$2,"ENTRADA",RODRIGO!$J$2:$J$2,$B13),0) -> 0 | J13: =IFERROR(SUMIFS(MOY!$M$2:$M$12,MOY!$H$2:$H$12,"ENTRADA",MOY!$J$2:$J$12,$B13),0) -> 0 | K13: =IFERROR(SUMIFS('NORMA RUTH'!$M$2:$M$12,'NORMA RUTH'!$H$2:$H$12,"ENTRADA",'NORMA RUTH'!$J$2:$J$12,$B13),0) -> 0 | L13: =IFERROR(SUMIFS(VALERIA!$M$2:$M$10,VALERIA!$H$2:$H$10,"ENTRADA",VALERIA!$J$2:$J$10,$B13),0) -> 0 | M13: =IFERROR(SUMIFS('MANUEL BANAMEX'!$M$2:$M$25,'MANUEL BANAMEX'!$H$2:$H$25,"ENTRADA",'MANUEL BANAMEX'!$J$2:$J$25,$B13),0) -> 0 | N13: =IFERROR(SUMIFS(ROBERTO!$M$2:$M$2,ROBERTO!$H$2:$H$2,"ENTRADA",ROBERTO!$J$2:$J$2,$B13),0) -> 0 | O13: =IFERROR(SUMIFS(JUAN!$M$2:$M$11,JUAN!$H$2:$H$11,"ENTRADA",JUAN!$J$2:$J$11,$B13),0) -> 0 | P13: =IFERROR(SUMIFS('NORMA SANCHEZ'!$M$2:$M$14,'NORMA SANCHEZ'!$H$2:$H$14,"ENTRADA",'NORMA SANCHEZ'!$J$2:$J$14,$B13),0) -> 0 | Q13: =IFERROR(SUMIFS('JOSE CARLOS'!$M$2:$M$16,'JOSE CARLOS'!$H$2:$H$16,"ENTRADA",'JOSE CARLOS'!$J$2:$J$16,$B13),0) -> 0 | R13: =IFERROR(SUMIFS('LUIS ENRIQUE '!$M$2:$M$21,'LUIS ENRIQUE '!$H$2:$H$21,"ENTRADA",'LUIS ENRIQUE '!$J$2:$J$21,$B13),0) -> 0 | S13: =IFERROR(SUMIFS(CESARIA!$M$2:$M$15,CESARIA!$H$2:$H$15,"ENTRADA",CESARIA!$J$2:$J$15,$B13),0) -> 0 | T13: =IFERROR(SUMIFS(ALAN!$M$2:$M$14,ALAN!$H$2:$H$14,"ENTRADA",ALAN!$J$2:$J$14,$B13),0) -> 0 | U13: =IFERROR(SUMIFS(ELVIA!$M$2:$M$6,ELVIA!$H$2:$H$6,"ENTRADA",ELVIA!$J$2:$J$6,$B13),0) -> 0 | V13: =IFERROR(SUMIFS(CAJA!$M$2:$M$586,CAJA!$H$2:$H$586,"ENTRADA",CAJA!$J$2:$J$586,$B13),0) -> 139080 | W13: =IFERROR(SUMIFS('CAJA TIGRES'!$M$2:$M$139,'CAJA TIGRES'!$H$2:$H$139,"ENTRADA",'CAJA TIGRES'!$J$2:$J$139,$B13),0) -> 0 | X13: =IFERROR(SUMIFS(RESERVA!$M$2:$M$2,RESERVA!$H$2:$H$2,"ENTRADA",RESERVA!$J$2:$J$2,$B13),0) -> 0 | Y13: =SUM(C13:X13) -> 139080 | Z13: =Y13 -> 139080
B14: TOTAL INGRESOS | C14: =SUM(C5:C13) -> 6887540 | D14: =SUM(D5:D13) -> 2018661 | E14: =SUM(E5:E13) -> 0 | F14: =SUM(F5:F13) -> 0 | G14: =SUM(G5:G13) -> 0 | H14: =SUM(H5:H13) -> 0 | I14: =SUM(I5:I13) -> 0 | J14: =SUM(J5:J13) -> 0 | ... Z14: =SUM(Z5:Z13) -> 10367858
B16: SALIDAS
A17: 1 | B17: RAYA | C17: =SUM(C18:C20) -> 0 | D17: =SUM(D18:D20) -> 0 | E17: =SUM(E18:E20) -> 0 | F17: =SUM(F18:F20) -> 0 | G17: =SUM(G18:G20) -> 0 | H17: =SUM(H18:H20) -> 0 | I17: =SUM(I18:I20) -> 0 | J17: =SUM(J18:J20) -> 0 | ... Z17: =SUM(Z18:Z20) -> 2979212.7
A18: 1.1 | B18: RAYA MGZ | C18: =IFERROR(SUMIFS('MGZ121'!$N$2:$N$175,'MGZ121'!H$2:H$175,"SALIDA",'MGZ121'!$J$2:$J$175,$B18),0) -> 0 | D18: =IFERROR(SUMIFS('MGZ BBVA'!$N$2:$N$88,'MGZ BBVA'!$H$2:$H$88,"SALIDA",'MGZ BBVA'!$J$2:$J$88,$B18),0) -> 0 | E18: =IFERROR(SUMIFS('MGZ DOLARES'!$N$2:$N$2,'MGZ DOLARES'!$F$2:$F$2,"SALIDA",'MGZ DOLARES'!$J$2:$J$2,$B18),0) -> 0 | F18: =IFERROR(SUMIFS('MGZ BAJIO'!$N$2:$N$4,'MGZ BAJIO'!$H$2:$H$4,"SALIDA",'MGZ BAJIO'!$J$2:$J$4,$B18),0) -> 0 | G18: =IFERROR(SUMIFS('VICTOR BANAMEX'!$N$2:$N$65,'VICTOR BANAMEX'!$H$2:$H$65,"SALIDA",'VICTOR BANAMEX'!$J$2:$J$65,$B18),0) -> 0 | H18: =IFERROR(SUMIFS('VICTOR BANORTE'!$N$2:$N$9,'VICTOR BANORTE'!$H$2:$H$9,"SALIDA",'VICTOR BANORTE'!$J$2:$J$9,$B18),0) -> 0 | I18: =IFERROR(SUMIFS(RODRIGO!$N$2:$N$2,RODRIGO!$H$2:$H$2,"SALIDA",RODRIGO!$J$2:$J$2,$B18),0) -> 0 | J18: =IFERROR(SUMIFS(MOY!$N$2:$N$12,MOY!$H$2:$H$12,"SALIDA",MOY!$J$2:$J$12,$B18),0) -> 0 | K18: =IFERROR(SUMIFS('NORMA RUTH'!$N$2:$N$12,'NORMA RUTH'!$H$2:$H$12,"SALIDA",'NORMA RUTH'!$J$2:$J$12,$B18),0) -> 0 | L18: =IFERROR(SUMIFS(VALERIA!$N$2:$N$10,VALERIA!$H$2:$H$10,"SALIDA",VALERIA!$J$2:$J$10,$B18),0) -> 0 | M18: =IFERROR(SUMIFS('MANUEL BANAMEX'!$N$2:$N$25,'MANUEL BANAMEX'!$H$2:$H$25,"SALIDA",'MANUEL BANAMEX'!$J$2:$J$25,$B18),0) -> 0 | N18: =IFERROR(SUMIFS(ROBERTO!$N$2:$N$2,ROBERTO!$H$2:$H$2,"SALIDA",ROBERTO!$J$2:$J$2,$B18),0) -> 0 | O18: =IFERROR(SUMIFS(JUAN!$N$2:$N$11,JUAN!$H$2:$H$11,"SALIDA",JUAN!$J$2:$J$11,$B18),0) -> 0 | P18: =IFERROR(SUMIFS('NORMA SANCHEZ'!$N$2:$N$14,'NORMA SANCHEZ'!$H$2:$H$14,"SALIDA",'NORMA SANCHEZ'!$J$2:$J$14,$B18),0) -> 0 | Q18: =IFERROR(SUMIFS('JOSE CARLOS'!$N$2:$N$16,'JOSE CARLOS'!$H$2:$H$16,"SALIDA",'JOSE CARLOS'!$J$2:$J$16,$B18),0) -> 0 | R18: =IFERROR(SUMIFS('LUIS ENRIQUE '!$N$2:$N$21,'LUIS ENRIQUE '!$H$2:$H$21,"SALIDA",'LUIS ENRIQUE '!$J$2:$J$21,$B18),0) -> 0 | S18: =IFERROR(SUMIFS(CESARIA!$N$2:$N$15,CESARIA!$H$2:$H$15,"SALIDA",CESARIA!$J$2:$J$15,$B18),0) -> 0 | T18: =IFERROR(SUMIFS(ALAN!$N$2:$N$14,ALAN!$H$2:$H$14,"SALIDA",ALAN!$J$2:$J$14,$B18),0) -> 0 | U18: =IFERROR(SUMIFS(ELVIA!$N$2:$N$6,ELVIA!$H$2:$H$6,"SALIDA",ELVIA!$J$2:$J$6,$B18),0) -> 0 | V18: =IFERROR(SUMIFS(CAJA!$N$2:$N$586,CAJA!$H$2:$H$586,"SALIDA",CAJA!$J$2:$J$586,$B18),0) -> 1814168.7 | W18: =IFERROR(SUMIFS('CAJA TIGRES'!$N$2:$N$139,'CAJA TIGRES'!$H$2:$H$139,"SALIDA",'CAJA TIGRES'!$J$2:$J$139,$B18),0) -> 747964 | X18: =IFERROR(SUMIFS(RESERVA!$N$2:$N$2,RESERVA!$H$2:$H$2,"SALIDA",RESERVA!$J$2:$J$2,$B18),0) -> 0 | Y18: =SUM(C18:X18) -> 2562132.7 | Z18: =Y18 -> 2562132.7
A19: 1.2 | B19: ANTICIPOS RAYA MGZ | C19: =IFERROR(SUMIFS('MGZ121'!$N$2:$N$175,'MGZ121'!H$2:H$175,"SALIDA",'MGZ121'!$J$2:$J$175,$B19),0) -> 0 | D19: =IFERROR(SUMIFS('MGZ BBVA'!$N$2:$N$88,'MGZ BBVA'!$H$2:$H$88,"SALIDA",'MGZ BBVA'!$J$2:$J$88,$B19),0) -> 0 | E19: =IFERROR(SUMIFS('MGZ DOLARES'!$N$2:$N$2,'MGZ DOLARES'!$F$2:$F$2,"SALIDA",'MGZ DOLARES'!$J$2:$J$2,$B19),0) -> 0 | F19: =IFERROR(SUMIFS('MGZ BAJIO'!$N$2:$N$4,'MGZ BAJIO'!$H$2:$H$4,"SALIDA",'MGZ BAJIO'!$J$2:$J$4,$B19),0) -> 0 | G19: =IFERROR(SUMIFS('VICTOR BANAMEX'!$N$2:$N$65,'VICTOR BANAMEX'!$H$2:$H$65,"SALIDA",'VICTOR BANAMEX'!$J$2:$J$65,$B19),0) -> 0 | H19: =IFERROR(SUMIFS('VICTOR BANORTE'!$N$2:$N$9,'VICTOR BANORTE'!$H$2:$H$9,"SALIDA",'VICTOR BANORTE'!$J$2:$J$9,$B19),0) -> 0 | I19: =IFERROR(SUMIFS(RODRIGO!$N$2:$N$2,RODRIGO!$H$2:$H$2,"SALIDA",RODRIGO!$J$2:$J$2,$B19),0) -> 0 | J19: =IFERROR(SUMIFS(MOY!$N$2:$N$12,MOY!$H$2:$H$12,"SALIDA",MOY!$J$2:$J$12,$B19),0) -> 0 | K19: =IFERROR(SUMIFS('NORMA RUTH'!$N$2:$N$12,'NORMA RUTH'!$H$2:$H$12,"SALIDA",'NORMA RUTH'!$J$2:$J$12,$B19),0) -> 0 | L19: =IFERROR(SUMIFS(VALERIA!$N$2:$N$10,VALERIA!$H$2:$H$10,"SALIDA",VALERIA!$J$2:$J$10,$B19),0) -> 0 | M19: =IFERROR(SUMIFS('MANUEL BANAMEX'!$N$2:$N$25,'MANUEL BANAMEX'!$H$2:$H$25,"SALIDA",'MANUEL BANAMEX'!$J$2:$J$25,$B19),0) -> 0 | N19: =IFERROR(SUMIFS(ROBERTO!$N$2:$N$2,ROBERTO!$H$2:$H$2,"SALIDA",ROBERTO!$J$2:$J$2,$B19),0) -> 0 | O19: =IFERROR(SUMIFS(JUAN!$N$2:$N$11,JUAN!$H$2:$H$11,"SALIDA",JUAN!$J$2:$J$11,$B19),0) -> 0 | P19: =IFERROR(SUMIFS('NORMA SANCHEZ'!$N$2:$N$14,'NORMA SANCHEZ'!$H$2:$H$14,"SALIDA",'NORMA SANCHEZ'!$J$2:$J$14,$B19),0) -> 0 | Q19: =IFERROR(SUMIFS('JOSE CARLOS'!$N$2:$N$16,'JOSE CARLOS'!$H$2:$H$16,"SALIDA",'JOSE CARLOS'!$J$2:$J$16,$B19),0) -> 0 | R19: =IFERROR(SUMIFS('LUIS ENRIQUE '!$N$2:$N$21,'LUIS ENRIQUE '!$H$2:$H$21,"SALIDA",'LUIS ENRIQUE '!$J$2:$J$21,$B19),0) -> 0 | S19: =IFERROR(SUMIFS(CESARIA!$N$2:$N$15,CESARIA!$H$2:$H$15,"SALIDA",CESARIA!$J$2:$J$15,$B19),0) -> 0 | T19: =IFERROR(SUMIFS(ALAN!$N$2:$N$14,ALAN!$H$2:$H$14,"SALIDA",ALAN!$J$2:$J$14,$B19),0) -> 0 | U19: =IFERROR(SUMIFS(ELVIA!$N$2:$N$6,ELVIA!$H$2:$H$6,"SALIDA",ELVIA!$J$2:$J$6,$B19),0) -> 0 | V19: =IFERROR(SUMIFS(CAJA!$N$2:$N$586,CAJA!$H$2:$H$586,"SALIDA",CAJA!$J$2:$J$586,$B19),0) -> 256663 | W19: =IFERROR(SUMIFS('CAJA TIGRES'!$N$2:$N$139,'CAJA TIGRES'!$H$2:$H$139,"SALIDA",'CAJA TIGRES'!$J$2:$J$139,$B19),0) -> 24900 | X19: =IFERROR(SUMIFS(RESERVA!$N$2:$N$2,RESERVA!$H$2:$H$2,"SALIDA",RESERVA!$J$2:$J$2,$B19),0) -> 0 | Y19: =SUM(C19:X19) -> 281563 | Z19: =Y19 -> 281563
A20: 1.3 | B20: RAYA GANADERIA | C20: =IFERROR(SUMIFS('MGZ121'!$N$2:$N$175,'MGZ121'!H$2:H$175,"SALIDA",'MGZ121'!$J$2:$J$175,$B20),0) -> 0 | D20: =IFERROR(SUMIFS('MGZ BBVA'!$N$2:$N$88,'MGZ BBVA'!$H$2:$H$88,"SALIDA",'MGZ BBVA'!$J$2:$J$88,$B20),0) -> 0 | E20: =IFERROR(SUMIFS('MGZ DOLARES'!$N$2:$N$2,'MGZ DOLARES'!$F$2:$F$2,"SALIDA",'MGZ DOLARES'!$J$2:$J$2,$B20),0) -> 0 | F20: =IFERROR(SUMIFS('MGZ BAJIO'!$N$2:$N$4,'MGZ BAJIO'!$H$2:$H$4,"SALIDA",'MGZ BAJIO'!$J$2:$J$4,$B20),0) -> 0 | G20: =IFERROR(SUMIFS('VICTOR BANAMEX'!$N$2:$N$65,'VICTOR BANAMEX'!$H$2:$H$65,"SALIDA",'VICTOR BANAMEX'!$J$2:$J$65,$B20),0) -> 0 | H20: =IFERROR(SUMIFS('VICTOR BANORTE'!$N$2:$N$9,'VICTOR BANORTE'!$H$2:$H$9,"SALIDA",'VICTOR BANORTE'!$J$2:$J$9,$B20),0) -> 0 | I20: =IFERROR(SUMIFS(RODRIGO!$N$2:$N$2,RODRIGO!$H$2:$H$2,"SALIDA",RODRIGO!$J$2:$J$2,$B20),0) -> 0 | J20: =IFERROR(SUMIFS(MOY!$N$2:$N$12,MOY!$H$2:$H$12,"SALIDA",MOY!$J$2:$J$12,$B20),0) -> 0 | K20: =IFERROR(SUMIFS('NORMA RUTH'!$N$2:$N$12,'NORMA RUTH'!$H$2:$H$12,"SALIDA",'NORMA RUTH'!$J$2:$J$12,$B20),0) -> 0 | L20: =IFERROR(SUMIFS(VALERIA!$N$2:$N$10,VALERIA!$H$2:$H$10,"SALIDA",VALERIA!$J$2:$J$10,$B20),0) -> 0 | M20: =IFERROR(SUMIFS('MANUEL BANAMEX'!$N$2:$N$25,'MANUEL BANAMEX'!$H$2:$H$25,"SALIDA",'MANUEL BANAMEX'!$J$2:$J$25,$B20),0) -> 0 | N20: =IFERROR(SUMIFS(ROBERTO!$N$2:$N$2,ROBERTO!$H$2:$H$2,"SALIDA",ROBERTO!$J$2:$J$2,$B20),0) -> 0 | O20: =IFERROR(SUMIFS(JUAN!$N$2:$N$11,JUAN!$H$2:$H$11,"SALIDA",JUAN!$J$2:$J$11,$B20),0) -> 0 | P20: =IFERROR(SUMIFS('NORMA SANCHEZ'!$N$2:$N$14,'NORMA SANCHEZ'!$H$2:$H$14,"SALIDA",'NORMA SANCHEZ'!$J$2:$J$14,$B20),0) -> 0 | Q20: =IFERROR(SUMIFS('JOSE CARLOS'!$N$2:$N$16,'JOSE CARLOS'!$H$2:$H$16,"SALIDA",'JOSE CARLOS'!$J$2:$J$16,$B20),0) -> 0 | R20: =IFERROR(SUMIFS('LUIS ENRIQUE '!$N$2:$N$21,'LUIS ENRIQUE '!$H$2:$H$21,"SALIDA",'LUIS ENRIQUE '!$J$2:$J$21,$B20),0) -> 0 | S20: =IFERROR(SUMIFS(CESARIA!$N$2:$N$15,CESARIA!$H$2:$H$15,"SALIDA",CESARIA!$J$2:$J$15,$B20),0) -> 0 | T20: =IFERROR(SUMIFS(ALAN!$N$2:$N$14,ALAN!$H$2:$H$14,"SALIDA",ALAN!$J$2:$J$14,$B20),0) -> 0 | U20: =IFERROR(SUMIFS(ELVIA!$N$2:$N$6,ELVIA!$H$2:$H$6,"SALIDA",ELVIA!$J$2:$J$6,$B20),0) -> 0 | V20: =IFERROR(SUMIFS(CAJA!$N$2:$N$586,CAJA!$H$2:$H$586,"SALIDA",CAJA!$J$2:$J$586,$B20),0) -> 114767 | W20: =IFERROR(SUMIFS('CAJA TIGRES'!$N$2:$N$139,'CAJA TIGRES'!$H$2:$H$139,"SALIDA",'CAJA TIGRES'!$J$2:$J$139,$B20),0) -> 20750 | X20: =IFERROR(SUMIFS(RESERVA!$N$2:$N$2,RESERVA!$H$2:$H$2,"SALIDA",RESERVA!$J$2:$J$2,$B20),0) -> 0 | Y20: =SUM(C20:X20) -> 135517 | Z20: =Y20 -> 135517
A21: 4 | B21: PRODUCCION | C21: =SUM(C22:C28) -> 1589681.3 | D21: =SUM(D22:D28) -> 130150 | E21: =SUM(E22:E28) -> 0 | F21: =SUM(F22:F28) -> 0 | G21: =SUM(G22:G28) -> 0 | H21: =SUM(H22:H28) -> 0 | I21: =SUM(I22:I28) -> 0 | J21: =SUM(J22:J28) -> 0 | ... Z21: =SUM(Z22:Z28) -> 1942361.3
A22: 4.1 | B22: FERTILIZANTES Y AGROQUIMICOS | C22: =IFERROR(SUMIFS('MGZ121'!$N$2:$N$175,'MGZ121'!H$2:H$175,"SALIDA",'MGZ121'!$J$2:$J$175,$B22),0) -> 1589681.3 | D22: =IFERROR(SUMIFS('MGZ BBVA'!$N$2:$N$88,'MGZ BBVA'!$H$2:$H$88,"SALIDA",'MGZ BBVA'!$J$2:$J$88,$B22),0) -> 130150 | E22: =IFERROR(SUMIFS('MGZ DOLARES'!$N$2:$N$2,'MGZ DOLARES'!$F$2:$F$2,"SALIDA",'MGZ DOLARES'!$J$2:$J$2,$B22),0) -> 0 | F22: =IFERROR(SUMIFS('MGZ BAJIO'!$N$2:$N$4,'MGZ BAJIO'!$H$2:$H$4,"SALIDA",'MGZ BAJIO'!$J$2:$J$4,$B22),0) -> 0 | G22: =IFERROR(SUMIFS('VICTOR BANAMEX'!$N$2:$N$65,'VICTOR BANAMEX'!$H$2:$H$65,"SALIDA",'VICTOR BANAMEX'!$J$2:$J$65,$B22),0) -> 0 | H22: =IFERROR(SUMIFS('VICTOR BANORTE'!$N$2:$N$9,'VICTOR BANORTE'!$H$2:$H$9,"SALIDA",'VICTOR BANORTE'!$J$2:$J$9,$B22),0) -> 0 | I22: =IFERROR(SUMIFS(RODRIGO!$N$2:$N$2,RODRIGO!$H$2:$H$2,"SALIDA",RODRIGO!$J$2:$J$2,$B22),0) -> 0 | J22: =IFERROR(SUMIFS(MOY!$N$2:$N$12,MOY!$H$2:$H$12,"SALIDA",MOY!$J$2:$J$12,$B22),0) -> 0 | K22: =IFERROR(SUMIFS('NORMA RUTH'!$N$2:$N$12,'NORMA RUTH'!$H$2:$H$12,"SALIDA",'NORMA RUTH'!$J$2:$J$12,$B22),0) -> 0 | L22: =IFERROR(SUMIFS(VALERIA!$N$2:$N$10,VALERIA!$H$2:$H$10,"SALIDA",VALERIA!$J$2:$J$10,$B22),0) -> 0 | M22: =IFERROR(SUMIFS('MANUEL BANAMEX'!$N$2:$N$25,'MANUEL BANAMEX'!$H$2:$H$25,"SALIDA",'MANUEL BANAMEX'!$J$2:$J$25,$B22),0) -> 25000 | N22: =IFERROR(SUMIFS(ROBERTO!$N$2:$N$2,ROBERTO!$H$2:$H$2,"SALIDA",ROBERTO!$J$2:$J$2,$B22),0) -> 0 | O22: =IFERROR(SUMIFS(JUAN!$N$2:$N$11,JUAN!$H$2:$H$11,"SALIDA",JUAN!$J$2:$J$11,$B22),0) -> 0 | P22: =IFERROR(SUMIFS('NORMA SANCHEZ'!$N$2:$N$14,'NORMA SANCHEZ'!$H$2:$H$14,"SALIDA",'NORMA SANCHEZ'!$J$2:$J$14,$B22),0) -> 0 | Q22: =IFERROR(SUMIFS('JOSE CARLOS'!$N$2:$N$16,'JOSE CARLOS'!$H$2:$H$16,"SALIDA",'JOSE CARLOS'!$J$2:$J$16,$B22),0) -> 0 | R22: =IFERROR(SUMIFS('LUIS ENRIQUE '!$N$2:$N$21,'LUIS ENRIQUE '!$H$2:$H$21,"SALIDA",'LUIS ENRIQUE '!$J$2:$J$21,$B22),0) -> 0 | S22: =IFERROR(SUMIFS(CESARIA!$N$2:$N$15,CESARIA!$H$2:$H$15,"SALIDA",CESARIA!$J$2:$J$15,$B22),0) -> 0 | T22: =IFERROR(SUMIFS(ALAN!$N$2:$N$14,ALAN!$H$2:$H$14,"SALIDA",ALAN!$J$2:$J$14,$B22),0) -> 0 | U22: =IFERROR(SUMIFS(ELVIA!$N$2:$N$6,ELVIA!$H$2:$H$6,"SALIDA",ELVIA!$J$2:$J$6,$B22),0) -> 0 | V22: =IFERROR(SUMIFS(CAJA!$N$2:$N$586,CAJA!$H$2:$H$586,"SALIDA",CAJA!$J$2:$J$586,$B22),0) -> 0 | W22: =IFERROR(SUMIFS('CAJA TIGRES'!$N$2:$N$139,'CAJA TIGRES'!$H$2:$H$139,"SALIDA",'CAJA TIGRES'!$J$2:$J$139,$B22),0) -> 0 | X22: =IFERROR(SUMIFS(RESERVA!$N$2:$N$2,RESERVA!$H$2:$H$2,"SALIDA",RESERVA!$J$2:$J$2,$B22),0) -> 0 | Y22: =SUM(C22:X22) -> 1744831.3 | Z22: =Y22 -> 1744831.3
A23: 4.2 | B23: ACOLCHADO PLASTICO | C23: =IFERROR(SUMIFS('MGZ121'!$N$2:$N$175,'MGZ121'!H$2:H$175,"SALIDA",'MGZ121'!$J$2:$J$175,$B23),0) -> 0 | D23: =IFERROR(SUMIFS('MGZ BBVA'!$N$2:$N$88,'MGZ BBVA'!$H$2:$H$88,"SALIDA",'MGZ BBVA'!$J$2:$J$88,$B23),0) -> 0 | E23: =IFERROR(SUMIFS('MGZ DOLARES'!$N$2:$N$2,'MGZ DOLARES'!$F$2:$F$2,"SALIDA",'MGZ DOLARES'!$J$2:$J$2,$B23),0) -> 0 | F23: =IFERROR(SUMIFS('MGZ BAJIO'!$N$2:$N$4,'MGZ BAJIO'!$H$2:$H$4,"SALIDA",'MGZ BAJIO'!$J$2:$J$4,$B23),0) -> 0 | G23: =IFERROR(SUMIFS('VICTOR BANAMEX'!$N$2:$N$65,'VICTOR BANAMEX'!$H$2:$H$65,"SALIDA",'VICTOR BANAMEX'!$J$2:$J$65,$B23),0) -> 0 | H23: =IFERROR(SUMIFS('VICTOR BANORTE'!$N$2:$N$9,'VICTOR BANORTE'!$H$2:$H$9,"SALIDA",'VICTOR BANORTE'!$J$2:$J$9,$B23),0) -> 0 | I23: =IFERROR(SUMIFS(RODRIGO!$N$2:$N$2,RODRIGO!$H$2:$H$2,"SALIDA",RODRIGO!$J$2:$J$2,$B23),0) -> 0 | J23: =IFERROR(SUMIFS(MOY!$N$2:$N$12,MOY!$H$2:$H$12,"SALIDA",MOY!$J$2:$J$12,$B23),0) -> 0 | K23: =IFERROR(SUMIFS('NORMA RUTH'!$N$2:$N$12,'NORMA RUTH'!$H$2:$H$12,"SALIDA",'NORMA RUTH'!$J$2:$J$12,$B23),0) -> 0 | L23: =IFERROR(SUMIFS(VALERIA!$N$2:$N$10,VALERIA!$H$2:$H$10,"SALIDA",VALERIA!$J$2:$J$10,$B23),0) -> 0 | M23: =IFERROR(SUMIFS('MANUEL BANAMEX'!$N$2:$N$25,'MANUEL BANAMEX'!$H$2:$H$25,"SALIDA",'MANUEL BANAMEX'!$J$2:$J$25,$B23),0) -> 0 | N23: =IFERROR(SUMIFS(ROBERTO!$N$2:$N$2,ROBERTO!$H$2:$H$2,"SALIDA",ROBERTO!$J$2:$J$2,$B23),0) -> 0 | O23: =IFERROR(SUMIFS(JUAN!$N$2:$N$11,JUAN!$H$2:$H$11,"SALIDA",JUAN!$J$2:$J$11,$B23),0) -> 0 | P23: =IFERROR(SUMIFS('NORMA SANCHEZ'!$N$2:$N$14,'NORMA SANCHEZ'!$H$2:$H$14,"SALIDA",'NORMA SANCHEZ'!$J$2:$J$14,$B23),0) -> 0 | Q23: =IFERROR(SUMIFS('JOSE CARLOS'!$N$2:$N$16,'JOSE CARLOS'!$H$2:$H$16,"SALIDA",'JOSE CARLOS'!$J$2:$J$16,$B23),0) -> 0 | R23: =IFERROR(SUMIFS('LUIS ENRIQUE '!$N$2:$N$21,'LUIS ENRIQUE '!$H$2:$H$21,"SALIDA",'LUIS ENRIQUE '!$J$2:$J$21,$B23),0) -> 0 | S23: =IFERROR(SUMIFS(CESARIA!$N$2:$N$15,CESARIA!$H$2:$H$15,"SALIDA",CESARIA!$J$2:$J$15,$B23),0) -> 0 | T23: =IFERROR(SUMIFS(ALAN!$N$2:$N$14,ALAN!$H$2:$H$14,"SALIDA",ALAN!$J$2:$J$14,$B23),0) -> 0 | U23: =IFERROR(SUMIFS(ELVIA!$N$2:$N$6,ELVIA!$H$2:$H$6,"SALIDA",ELVIA!$J$2:$J$6,$B23),0) -> 0 | V23: =IFERROR(SUMIFS(CAJA!$N$2:$N$586,CAJA!$H$2:$H$586,"SALIDA",CAJA!$J$2:$J$586,$B23),0) -> 0 | W23: =IFERROR(SUMIFS('CAJA TIGRES'!$N$2:$N$139,'CAJA TIGRES'!$H$2:$H$139,"SALIDA",'CAJA TIGRES'!$J$2:$J$139,$B23),0) -> 0 | X23: =IFERROR(SUMIFS(RESERVA!$N$2:$N$2,RESERVA!$H$2:$H$2,"SALIDA",RESERVA!$J$2:$J$2,$B23),0) -> 0 | Y23: =SUM(C23:X23) -> 0 | Z23: =Y23 -> 0
A24: 4.3 | B24: MALLA SOMBRA | C24: =IFERROR(SUMIFS('MGZ121'!$N$2:$N$175,'MGZ121'!H$2:H$175,"SALIDA",'MGZ121'!$J$2:$J$175,$B24),0) -> 0 | D24: =IFERROR(SUMIFS('MGZ BBVA'!$N$2:$N$88,'MGZ BBVA'!$H$2:$H$88,"SALIDA",'MGZ BBVA'!$J$2:$J$88,$B24),0) -> 0 | E24: =IFERROR(SUMIFS('MGZ DOLARES'!$N$2:$N$2,'MGZ DOLARES'!$F$2:$F$2,"SALIDA",'MGZ DOLARES'!$J$2:$J$2,$B24),0) -> 0 | F24: =IFERROR(SUMIFS('MGZ BAJIO'!$N$2:$N$4,'MGZ BAJIO'!$H$2:$H$4,"SALIDA",'MGZ BAJIO'!$J$2:$J$4,$B24),0) -> 0 | G24: =IFERROR(SUMIFS('VICTOR BANAMEX'!$N$2:$N$65,'VICTOR BANAMEX'!$H$2:$H$65,"SALIDA",'VICTOR BANAMEX'!$J$2:$J$65,$B24),0) -> 0 | H24: =IFERROR(SUMIFS('VICTOR BANORTE'!$N$2:$N$9,'VICTOR BANORTE'!$H$2:$H$9,"SALIDA",'VICTOR BANORTE'!$J$2:$J$9,$B24),0) -> 0 | I24: =IFERROR(SUMIFS(RODRIGO!$N$2:$N$2,RODRIGO!$H$2:$H$2,"SALIDA",RODRIGO!$J$2:$J$2,$B24),0) -> 0 | J24: =IFERROR(SUMIFS(MOY!$N$2:$N$12,MOY!$H$2:$H$12,"SALIDA",MOY!$J$2:$J$12,$B24),0) -> 0 | K24: =IFERROR(SUMIFS('NORMA RUTH'!$N$2:$N$12,'NORMA RUTH'!$H$2:$H$12,"SALIDA",'NORMA RUTH'!$J$2:$J$12,$B24),0) -> 0 | L24: =IFERROR(SUMIFS(VALERIA!$N$2:$N$10,VALERIA!$H$2:$H$10,"SALIDA",VALERIA!$J$2:$J$10,$B24),0) -> 0 | M24: =IFERROR(SUMIFS('MANUEL BANAMEX'!$N$2:$N$25,'MANUEL BANAMEX'!$H$2:$H$25,"SALIDA",'MANUEL BANAMEX'!$J$2:$J$25,$B24),0) -> 0 | N24: =IFERROR(SUMIFS(ROBERTO!$N$2:$N$2,ROBERTO!$H$2:$H$2,"SALIDA",ROBERTO!$J$2:$J$2,$B24),0) -> 0 | O24: =IFERROR(SUMIFS(JUAN!$N$2:$N$11,JUAN!$H$2:$H$11,"SALIDA",JUAN!$J$2:$J$11,$B24),0) -> 0 | P24: =IFERROR(SUMIFS('NORMA SANCHEZ'!$N$2:$N$14,'NORMA SANCHEZ'!$H$2:$H$14,"SALIDA",'NORMA SANCHEZ'!$J$2:$J$14,$B24),0) -> 0 | Q24: =IFERROR(SUMIFS('JOSE CARLOS'!$N$2:$N$16,'JOSE CARLOS'!$H$2:$H$16,"SALIDA",'JOSE CARLOS'!$J$2:$J$16,$B24),0) -> 0 | R24: =IFERROR(SUMIFS('LUIS ENRIQUE '!$N$2:$N$21,'LUIS ENRIQUE '!$H$2:$H$21,"SALIDA",'LUIS ENRIQUE '!$J$2:$J$21,$B24),0) -> 0 | S24: =IFERROR(SUMIFS(CESARIA!$N$2:$N$15,CESARIA!$H$2:$H$15,"SALIDA",CESARIA!$J$2:$J$15,$B24),0) -> 0 | T24: =IFERROR(SUMIFS(ALAN!$N$2:$N$14,ALAN!$H$2:$H$14,"SALIDA",ALAN!$J$2:$J$14,$B24),0) -> 0 | U24: =IFERROR(SUMIFS(ELVIA!$N$2:$N$6,ELVIA!$H$2:$H$6,"SALIDA",ELVIA!$J$2:$J$6,$B24),0) -> 0 | V24: =IFERROR(SUMIFS(CAJA!$N$2:$N$586,CAJA!$H$2:$H$586,"SALIDA",CAJA!$J$2:$J$586,$B24),0) -> 0 | W24: =IFERROR(SUMIFS('CAJA TIGRES'!$N$2:$N$139,'CAJA TIGRES'!$H$2:$H$139,"SALIDA",'CAJA TIGRES'!$J$2:$J$139,$B24),0) -> 0 | X24: =IFERROR(SUMIFS(RESERVA!$N$2:$N$2,RESERVA!$H$2:$H$2,"SALIDA",RESERVA!$J$2:$J$2,$B24),0) -> 0 | Y24: =SUM(C24:X24) -> 0 | Z24: =Y24 -> 0
A25: 4.4 | B25: CORTES Y FLETES | C25: =IFERROR(SUMIFS('MGZ121'!$N$2:$N$175,'MGZ121'!H$2:H$175,"SALIDA",'MGZ121'!$J$2:$J$175,$B25),0) -> 0 | D25: =IFERROR(SUMIFS('MGZ BBVA'!$N$2:$N$88,'MGZ BBVA'!$H$2:$H$88,"SALIDA",'MGZ BBVA'!$J$2:$J$88,$B25),0) -> 0 | E25: =IFERROR(SUMIFS('MGZ DOLARES'!$N$2:$N$2,'MGZ DOLARES'!$F$2:$F$2,"SALIDA",'MGZ DOLARES'!$J$2:$J$2,$B25),0) -> 0 | F25: =IFERROR(SUMIFS('MGZ BAJIO'!$N$2:$N$4,'MGZ BAJIO'!$H$2:$H$4,"SALIDA",'MGZ BAJIO'!$J$2:$J$4,$B25),0) -> 0 | G25: =IFERROR(SUMIFS('VICTOR BANAMEX'!$N$2:$N$65,'VICTOR BANAMEX'!$H$2:$H$65,"SALIDA",'VICTOR BANAMEX'!$J$2:$J$65,$B25),0) -> 0 | H25: =IFERROR(SUMIFS('VICTOR BANORTE'!$N$2:$N$9,'VICTOR BANORTE'!$H$2:$H$9,"SALIDA",'VICTOR BANORTE'!$J$2:$J$9,$B25),0) -> 0 | I25: =IFERROR(SUMIFS(RODRIGO!$N$2:$N$2,RODRIGO!$H$2:$H$2,"SALIDA",RODRIGO!$J$2:$J$2,$B25),0) -> 0 | J25: =IFERROR(SUMIFS(MOY!$N$2:$N$12,MOY!$H$2:$H$12,"SALIDA",MOY!$J$2:$J$12,$B25),0) -> 0 | K25: =IFERROR(SUMIFS('NORMA RUTH'!$N$2:$N$12,'NORMA RUTH'!$H$2:$H$12,"SALIDA",'NORMA RUTH'!$J$2:$J$12,$B25),0) -> 0 | L25: =IFERROR(SUMIFS(VALERIA!$N$2:$N$10,VALERIA!$H$2:$H$10,"SALIDA",VALERIA!$J$2:$J$10,$B25),0) -> 0 | M25: =IFERROR(SUMIFS('MANUEL BANAMEX'!$N$2:$N$25,'MANUEL BANAMEX'!$H$2:$H$25,"SALIDA",'MANUEL BANAMEX'!$J$2:$J$25,$B25),0) -> 0 | N25: =IFERROR(SUMIFS(ROBERTO!$N$2:$N$2,ROBERTO!$H$2:$H$2,"SALIDA",ROBERTO!$J$2:$J$2,$B25),0) -> 0 | O25: =IFERROR(SUMIFS(JUAN!$N$2:$N$11,JUAN!$H$2:$H$11,"SALIDA",JUAN!$J$2:$J$11,$B25),0) -> 0 | P25: =IFERROR(SUMIFS('NORMA SANCHEZ'!$N$2:$N$14,'NORMA SANCHEZ'!$H$2:$H$14,"SALIDA",'NORMA SANCHEZ'!$J$2:$J$14,$B25),0) -> 0 | Q25: =IFERROR(SUMIFS('JOSE CARLOS'!$N$2:$N$16,'JOSE CARLOS'!$H$2:$H$16,"SALIDA",'JOSE CARLOS'!$J$2:$J$16,$B25),0) -> 0 | R25: =IFERROR(SUMIFS('LUIS ENRIQUE '!$N$2:$N$21,'LUIS ENRIQUE '!$H$2:$H$21,"SALIDA",'LUIS ENRIQUE '!$J$2:$J$21,$B25),0) -> 0 | S25: =IFERROR(SUMIFS(CESARIA!$N$2:$N$15,CESARIA!$H$2:$H$15,"SALIDA",CESARIA!$J$2:$J$15,$B25),0) -> 0 | T25: =IFERROR(SUMIFS(ALAN!$N$2:$N$14,ALAN!$H$2:$H$14,"SALIDA",ALAN!$J$2:$J$14,$B25),0) -> 0 | U25: =IFERROR(SUMIFS(ELVIA!$N$2:$N$6,ELVIA!$H$2:$H$6,"SALIDA",ELVIA!$J$2:$J$6,$B25),0) -> 0 | V25: =IFERROR(SUMIFS(CAJA!$N$2:$N$586,CAJA!$H$2:$H$586,"SALIDA",CAJA!$J$2:$J$586,$B25),0) -> 144030 | W25: =IFERROR(SUMIFS('CAJA TIGRES'!$N$2:$N$139,'CAJA TIGRES'!$H$2:$H$139,"SALIDA",'CAJA TIGRES'!$J$2:$J$139,$B25),0) -> 0 | X25: =IFERROR(SUMIFS(RESERVA!$N$2:$N$2,RESERVA!$H$2:$H$2,"SALIDA",RESERVA!$J$2:$J$2,$B25),0) -> 0 | Y25: =SUM(C25:X25) -> 144030 | Z25: =Y25 -> 144030
B26: COMPRA DE PIÑAS | C26: =IFERROR(SUMIFS('MGZ121'!$N$2:$N$175,'MGZ121'!H$2:H$175,"SALIDA",'MGZ121'!$J$2:$J$175,$B26),0) -> 0 | D26: =IFERROR(SUMIFS('MGZ BBVA'!$N$2:$N$88,'MGZ BBVA'!$H$2:$H$88,"SALIDA",'MGZ BBVA'!$J$2:$J$88,$B26),0) -> 0 | E26: =IFERROR(SUMIFS('MGZ DOLARES'!$N$2:$N$2,'MGZ DOLARES'!$F$2:$F$2,"SALIDA",'MGZ DOLARES'!$J$2:$J$2,$B26),0) -> 0 | F26: =IFERROR(SUMIFS('MGZ BAJIO'!$N$2:$N$4,'MGZ BAJIO'!$H$2:$H$4,"SALIDA",'MGZ BAJIO'!$J$2:$J$4,$B26),0) -> 0 | G26: =IFERROR(SUMIFS('VICTOR BANAMEX'!$N$2:$N$65,'VICTOR BANAMEX'!$H$2:$H$65,"SALIDA",'VICTOR BANAMEX'!$J$2:$J$65,$B26),0) -> 0 | H26: =IFERROR(SUMIFS('VICTOR BANORTE'!$N$2:$N$9,'VICTOR BANORTE'!$H$2:$H$9,"SALIDA",'VICTOR BANORTE'!$J$2:$J$9,$B26),0) -> 0 | I26: =IFERROR(SUMIFS(RODRIGO!$N$2:$N$2,RODRIGO!$H$2:$H$2,"SALIDA",RODRIGO!$J$2:$J$2,$B26),0) -> 0 | J26: =IFERROR(SUMIFS(MOY!$N$2:$N$12,MOY!$H$2:$H$12,"SALIDA",MOY!$J$2:$J$12,$B26),0) -> 0 | K26: =IFERROR(SUMIFS('NORMA RUTH'!$N$2:$N$12,'NORMA RUTH'!$H$2:$H$12,"SALIDA",'NORMA RUTH'!$J$2:$J$12,$B26),0) -> 0 | L26: =IFERROR(SUMIFS(VALERIA!$N$2:$N$10,VALERIA!$H$2:$H$10,"SALIDA",VALERIA!$J$2:$J$10,$B26),0) -> 0 | M26: =IFERROR(SUMIFS('MANUEL BANAMEX'!$N$2:$N$25,'MANUEL BANAMEX'!$H$2:$H$25,"SALIDA",'MANUEL BANAMEX'!$J$2:$J$25,$B26),0) -> 0 | N26: =IFERROR(SUMIFS(ROBERTO!$N$2:$N$2,ROBERTO!$H$2:$H$2,"SALIDA",ROBERTO!$J$2:$J$2,$B26),0) -> 0 | O26: =IFERROR(SUMIFS(JUAN!$N$2:$N$11,JUAN!$H$2:$H$11,"SALIDA",JUAN!$J$2:$J$11,$B26),0) -> 0 | P26: =IFERROR(SUMIFS('NORMA SANCHEZ'!$N$2:$N$14,'NORMA SANCHEZ'!$H$2:$H$14,"SALIDA",'NORMA SANCHEZ'!$J$2:$J$14,$B26),0) -> 0 | Q26: =IFERROR(SUMIFS('JOSE CARLOS'!$N$2:$N$16,'JOSE CARLOS'!$H$2:$H$16,"SALIDA",'JOSE CARLOS'!$J$2:$J$16,$B26),0) -> 0 | R26: =IFERROR(SUMIFS('LUIS ENRIQUE '!$N$2:$N$21,'LUIS ENRIQUE '!$H$2:$H$21,"SALIDA",'LUIS ENRIQUE '!$J$2:$J$21,$B26),0) -> 0 | S26: =IFERROR(SUMIFS(CESARIA!$N$2:$N$15,CESARIA!$H$2:$H$15,"SALIDA",CESARIA!$J$2:$J$15,$B26),0) -> 0 | T26: =IFERROR(SUMIFS(ALAN!$N$2:$N$14,ALAN!$H$2:$H$14,"SALIDA",ALAN!$J$2:$J$14,$B26),0) -> 0 | U26: =IFERROR(SUMIFS(ELVIA!$N$2:$N$6,ELVIA!$H$2:$H$6,"SALIDA",ELVIA!$J$2:$J$6,$B26),0) -> 0 | V26: =IFERROR(SUMIFS(CAJA!$N$2:$N$586,CAJA!$H$2:$H$586,"SALIDA",CAJA!$J$2:$J$586,$B26),0) -> 0 | W26: =IFERROR(SUMIFS('CAJA TIGRES'!$N$2:$N$139,'CAJA TIGRES'!$H$2:$H$139,"SALIDA",'CAJA TIGRES'!$J$2:$J$139,$B26),0) -> 0 | X26: =IFERROR(SUMIFS(RESERVA!$N$2:$N$2,RESERVA!$H$2:$H$2,"SALIDA",RESERVA!$J$2:$J$2,$B26),0) -> 0 | Y26: =SUM(C26:X26) -> 0 | Z26: =Y26 -> 0
B27: CORTES POMELERO | C27: =IFERROR(SUMIFS('MGZ121'!$N$2:$N$175,'MGZ121'!H$2:H$175,"SALIDA",'MGZ121'!$J$2:$J$175,$B27),0) -> 0 | D27: =IFERROR(SUMIFS('MGZ BBVA'!$N$2:$N$88,'MGZ BBVA'!$H$2:$H$88,"SALIDA",'MGZ BBVA'!$J$2:$J$88,$B27),0) -> 0 | E27: =IFERROR(SUMIFS('MGZ DOLARES'!$N$2:$N$2,'MGZ DOLARES'!$F$2:$F$2,"SALIDA",'MGZ DOLARES'!$J$2:$J$2,$B27),0) -> 0 | F27: =IFERROR(SUMIFS('MGZ BAJIO'!$N$2:$N$4,'MGZ BAJIO'!$H$2:$H$4,"SALIDA",'MGZ BAJIO'!$J$2:$J$4,$B27),0) -> 0 | G27: =IFERROR(SUMIFS('VICTOR BANAMEX'!$N$2:$N$65,'VICTOR BANAMEX'!$H$2:$H$65,"SALIDA",'VICTOR BANAMEX'!$J$2:$J$65,$B27),0) -> 0 | H27: =IFERROR(SUMIFS('VICTOR BANORTE'!$N$2:$N$9,'VICTOR BANORTE'!$H$2:$H$9,"SALIDA",'VICTOR BANORTE'!$J$2:$J$9,$B27),0) -> 0 | I27: =IFERROR(SUMIFS(RODRIGO!$N$2:$N$2,RODRIGO!$H$2:$H$2,"SALIDA",RODRIGO!$J$2:$J$2,$B27),0) -> 0 | J27: =IFERROR(SUMIFS(MOY!$N$2:$N$12,MOY!$H$2:$H$12,"SALIDA",MOY!$J$2:$J$12,$B27),0) -> 0 | K27: =IFERROR(SUMIFS('NORMA RUTH'!$N$2:$N$12,'NORMA RUTH'!$H$2:$H$12,"SALIDA",'NORMA RUTH'!$J$2:$J$12,$B27),0) -> 0 | L27: =IFERROR(SUMIFS(VALERIA!$N$2:$N$10,VALERIA!$H$2:$H$10,"SALIDA",VALERIA!$J$2:$J$10,$B27),0) -> 0 | M27: =IFERROR(SUMIFS('MANUEL BANAMEX'!$N$2:$N$25,'MANUEL BANAMEX'!$H$2:$H$25,"SALIDA",'MANUEL BANAMEX'!$J$2:$J$25,$B27),0) -> 0 | N27: =IFERROR(SUMIFS(ROBERTO!$N$2:$N$2,ROBERTO!$H$2:$H$2,"SALIDA",ROBERTO!$J$2:$J$2,$B27),0) -> 0 | O27: =IFERROR(SUMIFS(JUAN!$N$2:$N$11,JUAN!$H$2:$H$11,"SALIDA",JUAN!$J$2:$J$11,$B27),0) -> 0 | P27: =IFERROR(SUMIFS('NORMA SANCHEZ'!$N$2:$N$14,'NORMA SANCHEZ'!$H$2:$H$14,"SALIDA",'NORMA SANCHEZ'!$J$2:$J$14,$B27),0) -> 0 | Q27: =IFERROR(SUMIFS('JOSE CARLOS'!$N$2:$N$16,'JOSE CARLOS'!$H$2:$H$16,"SALIDA",'JOSE CARLOS'!$J$2:$J$16,$B27),0) -> 0 | R27: =IFERROR(SUMIFS('LUIS ENRIQUE '!$N$2:$N$21,'LUIS ENRIQUE '!$H$2:$H$21,"SALIDA",'LUIS ENRIQUE '!$J$2:$J$21,$B27),0) -> 0 | S27: =IFERROR(SUMIFS(CESARIA!$N$2:$N$15,CESARIA!$H$2:$H$15,"SALIDA",CESARIA!$J$2:$J$15,$B27),0) -> 0 | T27: =IFERROR(SUMIFS(ALAN!$N$2:$N$14,ALAN!$H$2:$H$14,"SALIDA",ALAN!$J$2:$J$14,$B27),0) -> 0 | U27: =IFERROR(SUMIFS(ELVIA!$N$2:$N$6,ELVIA!$H$2:$H$6,"SALIDA",ELVIA!$J$2:$J$6,$B27),0) -> 0 | V27: =IFERROR(SUMIFS(CAJA!$N$2:$N$586,CAJA!$H$2:$H$586,"SALIDA",CAJA!$J$2:$J$586,$B27),0) -> 0 | W27: =IFERROR(SUMIFS('CAJA TIGRES'!$N$2:$N$139,'CAJA TIGRES'!$H$2:$H$139,"SALIDA",'CAJA TIGRES'!$J$2:$J$139,$B27),0) -> 0 | X27: =IFERROR(SUMIFS(RESERVA!$N$2:$N$2,RESERVA!$H$2:$H$2,"SALIDA",RESERVA!$J$2:$J$2,$B27),0) -> 0 | Y27: =SUM(C27:X27) -> 0 | Z27: =Y27 -> 0
B28: PRESTAMO CHOFER | C28: =IFERROR(SUMIFS('MGZ121'!$N$2:$N$175,'MGZ121'!H$2:H$175,"SALIDA",'MGZ121'!$J$2:$J$175,$B28),0) -> 0 | D28: =IFERROR(SUMIFS('MGZ BBVA'!$N$2:$N$88,'MGZ BBVA'!$H$2:$H$88,"SALIDA",'MGZ BBVA'!$J$2:$J$88,$B28),0) -> 0 | E28: =IFERROR(SUMIFS('MGZ DOLARES'!$N$2:$N$2,'MGZ DOLARES'!$F$2:$F$2,"SALIDA",'MGZ DOLARES'!$J$2:$J$2,$B28),0) -> 0 | F28: =IFERROR(SUMIFS('MGZ BAJIO'!$N$2:$N$4,'MGZ BAJIO'!$H$2:$H$4,"SALIDA",'MGZ BAJIO'!$J$2:$J$4,$B28),0) -> 0 | G28: =IFERROR(SUMIFS('VICTOR BANAMEX'!$N$2:$N$65,'VICTOR BANAMEX'!$H$2:$H$65,"SALIDA",'VICTOR BANAMEX'!$J$2:$J$65,$B28),0) -> 0 | H28: =IFERROR(SUMIFS('VICTOR BANORTE'!$N$2:$N$9,'VICTOR BANORTE'!$H$2:$H$9,"SALIDA",'VICTOR BANORTE'!$J$2:$J$9,$B28),0) -> 0 | I28: =IFERROR(SUMIFS(RODRIGO!$N$2:$N$2,RODRIGO!$H$2:$H$2,"SALIDA",RODRIGO!$J$2:$J$2,$B28),0) -> 0 | J28: =IFERROR(SUMIFS(MOY!$N$2:$N$12,MOY!$H$2:$H$12,"SALIDA",MOY!$J$2:$J$12,$B28),0) -> 0 | K28: =IFERROR(SUMIFS('NORMA RUTH'!$N$2:$N$12,'NORMA RUTH'!$H$2:$H$12,"SALIDA",'NORMA RUTH'!$J$2:$J$12,$B28),0) -> 0 | L28: =IFERROR(SUMIFS(VALERIA!$N$2:$N$10,VALERIA!$H$2:$H$10,"SALIDA",VALERIA!$J$2:$J$10,$B28),0) -> 0 | M28: =IFERROR(SUMIFS('MANUEL BANAMEX'!$N$2:$N$25,'MANUEL BANAMEX'!$H$2:$H$25,"SALIDA",'MANUEL BANAMEX'!$J$2:$J$25,$B28),0) -> 0 | N28: =IFERROR(SUMIFS(ROBERTO!$N$2:$N$2,ROBERTO!$H$2:$H$2,"SALIDA",ROBERTO!$J$2:$J$2,$B28),0) -> 0 | O28: =IFERROR(SUMIFS(JUAN!$N$2:$N$11,JUAN!$H$2:$H$11,"SALIDA",JUAN!$J$2:$J$11,$B28),0) -> 0 | P28: =IFERROR(SUMIFS('NORMA SANCHEZ'!$N$2:$N$14,'NORMA SANCHEZ'!$H$2:$H$14,"SALIDA",'NORMA SANCHEZ'!$J$2:$J$14,$B28),0) -> 0 | Q28: =IFERROR(SUMIFS('JOSE CARLOS'!$N$2:$N$16,'JOSE CARLOS'!$H$2:$H$16,"SALIDA",'JOSE CARLOS'!$J$2:$J$16,$B28),0) -> 0 | R28: =IFERROR(SUMIFS('LUIS ENRIQUE '!$N$2:$N$21,'LUIS ENRIQUE '!$H$2:$H$21,"SALIDA",'LUIS ENRIQUE '!$J$2:$J$21,$B28),0) -> 0 | S28: =IFERROR(SUMIFS(CESARIA!$N$2:$N$15,CESARIA!$H$2:$H$15,"SALIDA",CESARIA!$J$2:$J$15,$B28),0) -> 0 | T28: =IFERROR(SUMIFS(ALAN!$N$2:$N$14,ALAN!$H$2:$H$14,"SALIDA",ALAN!$J$2:$J$14,$B28),0) -> 0 | U28: =IFERROR(SUMIFS(ELVIA!$N$2:$N$6,ELVIA!$H$2:$H$6,"SALIDA",ELVIA!$J$2:$J$6,$B28),0) -> 0 | V28: =IFERROR(SUMIFS(CAJA!$N$2:$N$586,CAJA!$H$2:$H$586,"SALIDA",CAJA!$J$2:$J$586,$B28),0) -> 53500 | W28: =IFERROR(SUMIFS('CAJA TIGRES'!$N$2:$N$139,'CAJA TIGRES'!$H$2:$H$139,"SALIDA",'CAJA TIGRES'!$J$2:$J$139,$B28),0) -> 0 | X28: =IFERROR(SUMIFS(RESERVA!$N$2:$N$2,RESERVA!$H$2:$H$2,"SALIDA",RESERVA!$J$2:$J$2,$B28),0) -> 0 | Y28: =SUM(C28:X28) -> 53500 | Z28: =Y28 -> 53500
A29: 5 | B29: OPERACION | C29: =SUM(C30:C48) -> 356709.74 | D29: =SUM(D30:D48) -> 856259.52 | E29: =SUM(E30:E48) -> 0 | F29: =SUM(F30:F48) -> 0 | G29: =SUM(G30:G48) -> 148474.29 | H29: =SUM(H30:H48) -> 0 | I29: =SUM(I30:I48) -> 0 | J29: =SUM(J30:J48) -> 0 | ... Z29: =SUM(Z30:Z48) -> 1862676.6
A30: 5.1 | B30: SERVICIOS MECANICOS | C30: =IFERROR(SUMIFS('MGZ121'!$N$2:$N$175,'MGZ121'!H$2:H$175,"SALIDA",'MGZ121'!$J$2:$J$175,$B30),0) -> 0 | D30: =IFERROR(SUMIFS('MGZ BBVA'!$N$2:$N$88,'MGZ BBVA'!$H$2:$H$88,"SALIDA",'MGZ BBVA'!$J$2:$J$88,$B30),0) -> 49085 | E30: =IFERROR(SUMIFS('MGZ DOLARES'!$N$2:$N$2,'MGZ DOLARES'!$F$2:$F$2,"SALIDA",'MGZ DOLARES'!$J$2:$J$2,$B30),0) -> 0 | F30: =IFERROR(SUMIFS('MGZ BAJIO'!$N$2:$N$4,'MGZ BAJIO'!$H$2:$H$4,"SALIDA",'MGZ BAJIO'!$J$2:$J$4,$B30),0) -> 0 | G30: =IFERROR(SUMIFS('VICTOR BANAMEX'!$N$2:$N$65,'VICTOR BANAMEX'!$H$2:$H$65,"SALIDA",'VICTOR BANAMEX'!$J$2:$J$65,$B30),0) -> 0 | H30: =IFERROR(SUMIFS('VICTOR BANORTE'!$N$2:$N$9,'VICTOR BANORTE'!$H$2:$H$9,"SALIDA",'VICTOR BANORTE'!$J$2:$J$9,$B30),0) -> 0 | I30: =IFERROR(SUMIFS(RODRIGO!$N$2:$N$2,RODRIGO!$H$2:$H$2,"SALIDA",RODRIGO!$J$2:$J$2,$B30),0) -> 0 | J30: =IFERROR(SUMIFS(MOY!$N$2:$N$12,MOY!$H$2:$H$12,"SALIDA",MOY!$J$2:$J$12,$B30),0) -> 0 | K30: =IFERROR(SUMIFS('NORMA RUTH'!$N$2:$N$12,'NORMA RUTH'!$H$2:$H$12,"SALIDA",'NORMA RUTH'!$J$2:$J$12,$B30),0) -> 0 | L30: =IFERROR(SUMIFS(VALERIA!$N$2:$N$10,VALERIA!$H$2:$H$10,"SALIDA",VALERIA!$J$2:$J$10,$B30),0) -> 0 | M30: =IFERROR(SUMIFS('MANUEL BANAMEX'!$N$2:$N$25,'MANUEL BANAMEX'!$H$2:$H$25,"SALIDA",'MANUEL BANAMEX'!$J$2:$J$25,$B30),0) -> 0 | N30: =IFERROR(SUMIFS(ROBERTO!$N$2:$N$2,ROBERTO!$H$2:$H$2,"SALIDA",ROBERTO!$J$2:$J$2,$B30),0) -> 0 | O30: =IFERROR(SUMIFS(JUAN!$N$2:$N$11,JUAN!$H$2:$H$11,"SALIDA",JUAN!$J$2:$J$11,$B30),0) -> 0 | P30: =IFERROR(SUMIFS('NORMA SANCHEZ'!$N$2:$N$14,'NORMA SANCHEZ'!$H$2:$H$14,"SALIDA",'NORMA SANCHEZ'!$J$2:$J$14,$B30),0) -> 0 | Q30: =IFERROR(SUMIFS('JOSE CARLOS'!$N$2:$N$16,'JOSE CARLOS'!$H$2:$H$16,"SALIDA",'JOSE CARLOS'!$J$2:$J$16,$B30),0) -> 0 | R30: =IFERROR(SUMIFS('LUIS ENRIQUE '!$N$2:$N$21,'LUIS ENRIQUE '!$H$2:$H$21,"SALIDA",'LUIS ENRIQUE '!$J$2:$J$21,$B30),0) -> 0 | S30: =IFERROR(SUMIFS(CESARIA!$N$2:$N$15,CESARIA!$H$2:$H$15,"SALIDA",CESARIA!$J$2:$J$15,$B30),0) -> 0 | T30: =IFERROR(SUMIFS(ALAN!$N$2:$N$14,ALAN!$H$2:$H$14,"SALIDA",ALAN!$J$2:$J$14,$B30),0) -> 0 | U30: =IFERROR(SUMIFS(ELVIA!$N$2:$N$6,ELVIA!$H$2:$H$6,"SALIDA",ELVIA!$J$2:$J$6,$B30),0) -> 0 | V30: =IFERROR(SUMIFS(CAJA!$N$2:$N$586,CAJA!$H$2:$H$586,"SALIDA",CAJA!$J$2:$J$586,$B30),0) -> 27365 | W30: =IFERROR(SUMIFS('CAJA TIGRES'!$N$2:$N$139,'CAJA TIGRES'!$H$2:$H$139,"SALIDA",'CAJA TIGRES'!$J$2:$J$139,$B30),0) -> 24395 | X30: =IFERROR(SUMIFS(RESERVA!$N$2:$N$2,RESERVA!$H$2:$H$2,"SALIDA",RESERVA!$J$2:$J$2,$B30),0) -> 0 | Y30: =SUM(C30:X30) -> 100845 | Z30: =Y30 -> 100845
A31: 5.2 | B31: REFACCIONES MAQUINARIA Y VEHICULOS | C31: =IFERROR(SUMIFS('MGZ121'!$N$2:$N$175,'MGZ121'!H$2:H$175,"SALIDA",'MGZ121'!$J$2:$J$175,$B31),0) -> 42305 | D31: =IFERROR(SUMIFS('MGZ BBVA'!$N$2:$N$88,'MGZ BBVA'!$H$2:$H$88,"SALIDA",'MGZ BBVA'!$J$2:$J$88,$B31),0) -> 226545.09 | E31: =IFERROR(SUMIFS('MGZ DOLARES'!$N$2:$N$2,'MGZ DOLARES'!$F$2:$F$2,"SALIDA",'MGZ DOLARES'!$J$2:$J$2,$B31),0) -> 0 | F31: =IFERROR(SUMIFS('MGZ BAJIO'!$N$2:$N$4,'MGZ BAJIO'!$H$2:$H$4,"SALIDA",'MGZ BAJIO'!$J$2:$J$4,$B31),0) -> 0 | G31: =IFERROR(SUMIFS('VICTOR BANAMEX'!$N$2:$N$65,'VICTOR BANAMEX'!$H$2:$H$65,"SALIDA",'VICTOR BANAMEX'!$J$2:$J$65,$B31),0) -> 0 | H31: =IFERROR(SUMIFS('VICTOR BANORTE'!$N$2:$N$9,'VICTOR BANORTE'!$H$2:$H$9,"SALIDA",'VICTOR BANORTE'!$J$2:$J$9,$B31),0) -> 0 | I31: =IFERROR(SUMIFS(RODRIGO!$N$2:$N$2,RODRIGO!$H$2:$H$2,"SALIDA",RODRIGO!$J$2:$J$2,$B31),0) -> 0 | J31: =IFERROR(SUMIFS(MOY!$N$2:$N$12,MOY!$H$2:$H$12,"SALIDA",MOY!$J$2:$J$12,$B31),0) -> 0 | K31: =IFERROR(SUMIFS('NORMA RUTH'!$N$2:$N$12,'NORMA RUTH'!$H$2:$H$12,"SALIDA",'NORMA RUTH'!$J$2:$J$12,$B31),0) -> 0 | L31: =IFERROR(SUMIFS(VALERIA!$N$2:$N$10,VALERIA!$H$2:$H$10,"SALIDA",VALERIA!$J$2:$J$10,$B31),0) -> 0 | M31: =IFERROR(SUMIFS('MANUEL BANAMEX'!$N$2:$N$25,'MANUEL BANAMEX'!$H$2:$H$25,"SALIDA",'MANUEL BANAMEX'!$J$2:$J$25,$B31),0) -> 7000 | N31: =IFERROR(SUMIFS(ROBERTO!$N$2:$N$2,ROBERTO!$H$2:$H$2,"SALIDA",ROBERTO!$J$2:$J$2,$B31),0) -> 0 | O31: =IFERROR(SUMIFS(JUAN!$N$2:$N$11,JUAN!$H$2:$H$11,"SALIDA",JUAN!$J$2:$J$11,$B31),0) -> 0 | P31: =IFERROR(SUMIFS('NORMA SANCHEZ'!$N$2:$N$14,'NORMA SANCHEZ'!$H$2:$H$14,"SALIDA",'NORMA SANCHEZ'!$J$2:$J$14,$B31),0) -> 0 | Q31: =IFERROR(SUMIFS('JOSE CARLOS'!$N$2:$N$16,'JOSE CARLOS'!$H$2:$H$16,"SALIDA",'JOSE CARLOS'!$J$2:$J$16,$B31),0) -> 0 | R31: =IFERROR(SUMIFS('LUIS ENRIQUE '!$N$2:$N$21,'LUIS ENRIQUE '!$H$2:$H$21,"SALIDA",'LUIS ENRIQUE '!$J$2:$J$21,$B31),0) -> 0 | S31: =IFERROR(SUMIFS(CESARIA!$N$2:$N$15,CESARIA!$H$2:$H$15,"SALIDA",CESARIA!$J$2:$J$15,$B31),0) -> 0 | T31: =IFERROR(SUMIFS(ALAN!$N$2:$N$14,ALAN!$H$2:$H$14,"SALIDA",ALAN!$J$2:$J$14,$B31),0) -> 0 | U31: =IFERROR(SUMIFS(ELVIA!$N$2:$N$6,ELVIA!$H$2:$H$6,"SALIDA",ELVIA!$J$2:$J$6,$B31),0) -> 0 | V31: =IFERROR(SUMIFS(CAJA!$N$2:$N$586,CAJA!$H$2:$H$586,"SALIDA",CAJA!$J$2:$J$586,$B31),0) -> 22745 | W31: =IFERROR(SUMIFS('CAJA TIGRES'!$N$2:$N$139,'CAJA TIGRES'!$H$2:$H$139,"SALIDA",'CAJA TIGRES'!$J$2:$J$139,$B31),0) -> 8780 | X31: =IFERROR(SUMIFS(RESERVA!$N$2:$N$2,RESERVA!$H$2:$H$2,"SALIDA",RESERVA!$J$2:$J$2,$B31),0) -> 0 | Y31: =SUM(C31:X31) -> 307375.09 | Z31: =Y31 -> 307375.09
A32: 5.3 | B32: COMBUSTIBLE | C32: =IFERROR(SUMIFS('MGZ121'!$N$2:$N$175,'MGZ121'!H$2:H$175,"SALIDA",'MGZ121'!$J$2:$J$175,$B32),0) -> 286868.91 | D32: =IFERROR(SUMIFS('MGZ BBVA'!$N$2:$N$88,'MGZ BBVA'!$H$2:$H$88,"SALIDA",'MGZ BBVA'!$J$2:$J$88,$B32),0) -> 508798.77 | E32: =IFERROR(SUMIFS('MGZ DOLARES'!$N$2:$N$2,'MGZ DOLARES'!$F$2:$F$2,"SALIDA",'MGZ DOLARES'!$J$2:$J$2,$B32),0) -> 0 | F32: =IFERROR(SUMIFS('MGZ BAJIO'!$N$2:$N$4,'MGZ BAJIO'!$H$2:$H$4,"SALIDA",'MGZ BAJIO'!$J$2:$J$4,$B32),0) -> 0 | G32: =IFERROR(SUMIFS('VICTOR BANAMEX'!$N$2:$N$65,'VICTOR BANAMEX'!$H$2:$H$65,"SALIDA",'VICTOR BANAMEX'!$J$2:$J$65,$B32),0) -> 0 | H32: =IFERROR(SUMIFS('VICTOR BANORTE'!$N$2:$N$9,'VICTOR BANORTE'!$H$2:$H$9,"SALIDA",'VICTOR BANORTE'!$J$2:$J$9,$B32),0) -> 0 | I32: =IFERROR(SUMIFS(RODRIGO!$N$2:$N$2,RODRIGO!$H$2:$H$2,"SALIDA",RODRIGO!$J$2:$J$2,$B32),0) -> 0 | J32: =IFERROR(SUMIFS(MOY!$N$2:$N$12,MOY!$H$2:$H$12,"SALIDA",MOY!$J$2:$J$12,$B32),0) -> 0 | K32: =IFERROR(SUMIFS('NORMA RUTH'!$N$2:$N$12,'NORMA RUTH'!$H$2:$H$12,"SALIDA",'NORMA RUTH'!$J$2:$J$12,$B32),0) -> 0 | L32: =IFERROR(SUMIFS(VALERIA!$N$2:$N$10,VALERIA!$H$2:$H$10,"SALIDA",VALERIA!$J$2:$J$10,$B32),0) -> 0 | M32: =IFERROR(SUMIFS('MANUEL BANAMEX'!$N$2:$N$25,'MANUEL BANAMEX'!$H$2:$H$25,"SALIDA",'MANUEL BANAMEX'!$J$2:$J$25,$B32),0) -> 0 | N32: =IFERROR(SUMIFS(ROBERTO!$N$2:$N$2,ROBERTO!$H$2:$H$2,"SALIDA",ROBERTO!$J$2:$J$2,$B32),0) -> 0 | O32: =IFERROR(SUMIFS(JUAN!$N$2:$N$11,JUAN!$H$2:$H$11,"SALIDA",JUAN!$J$2:$J$11,$B32),0) -> 0 | P32: =IFERROR(SUMIFS('NORMA SANCHEZ'!$N$2:$N$14,'NORMA SANCHEZ'!$H$2:$H$14,"SALIDA",'NORMA SANCHEZ'!$J$2:$J$14,$B32),0) -> 0 | Q32: =IFERROR(SUMIFS('JOSE CARLOS'!$N$2:$N$16,'JOSE CARLOS'!$H$2:$H$16,"SALIDA",'JOSE CARLOS'!$J$2:$J$16,$B32),0) -> 0 | R32: =IFERROR(SUMIFS('LUIS ENRIQUE '!$N$2:$N$21,'LUIS ENRIQUE '!$H$2:$H$21,"SALIDA",'LUIS ENRIQUE '!$J$2:$J$21,$B32),0) -> 0 | S32: =IFERROR(SUMIFS(CESARIA!$N$2:$N$15,CESARIA!$H$2:$H$15,"SALIDA",CESARIA!$J$2:$J$15,$B32),0) -> 0 | T32: =IFERROR(SUMIFS(ALAN!$N$2:$N$14,ALAN!$H$2:$H$14,"SALIDA",ALAN!$J$2:$J$14,$B32),0) -> 0 | U32: =IFERROR(SUMIFS(ELVIA!$N$2:$N$6,ELVIA!$H$2:$H$6,"SALIDA",ELVIA!$J$2:$J$6,$B32),0) -> 0 | V32: =IFERROR(SUMIFS(CAJA!$N$2:$N$586,CAJA!$H$2:$H$586,"SALIDA",CAJA!$J$2:$J$586,$B32),0) -> 500 | W32: =IFERROR(SUMIFS('CAJA TIGRES'!$N$2:$N$139,'CAJA TIGRES'!$H$2:$H$139,"SALIDA",'CAJA TIGRES'!$J$2:$J$139,$B32),0) -> 0 | X32: =IFERROR(SUMIFS(RESERVA!$N$2:$N$2,RESERVA!$H$2:$H$2,"SALIDA",RESERVA!$J$2:$J$2,$B32),0) -> 0 | Y32: =SUM(C32:X32) -> 796167.68 | Z32: =Y32 -> 796167.68
A33: 5.4 | B33: MATERIALES VARIOS | C33: =IFERROR(SUMIFS('MGZ121'!$N$2:$N$175,'MGZ121'!H$2:H$175,"SALIDA",'MGZ121'!$J$2:$J$175,$B33),0) -> 17920 | D33: =IFERROR(SUMIFS('MGZ BBVA'!$N$2:$N$88,'MGZ BBVA'!$H$2:$H$88,"SALIDA",'MGZ BBVA'!$J$2:$J$88,$B33),0) -> 0 | E33: =IFERROR(SUMIFS('MGZ DOLARES'!$N$2:$N$2,'MGZ DOLARES'!$F$2:$F$2,"SALIDA",'MGZ DOLARES'!$J$2:$J$2,$B33),0) -> 0 | F33: =IFERROR(SUMIFS('MGZ BAJIO'!$N$2:$N$4,'MGZ BAJIO'!$H$2:$H$4,"SALIDA",'MGZ BAJIO'!$J$2:$J$4,$B33),0) -> 0 | G33: =IFERROR(SUMIFS('VICTOR BANAMEX'!$N$2:$N$65,'VICTOR BANAMEX'!$H$2:$H$65,"SALIDA",'VICTOR BANAMEX'!$J$2:$J$65,$B33),0) -> 0 | H33: =IFERROR(SUMIFS('VICTOR BANORTE'!$N$2:$N$9,'VICTOR BANORTE'!$H$2:$H$9,"SALIDA",'VICTOR BANORTE'!$J$2:$J$9,$B33),0) -> 0 | I33: =IFERROR(SUMIFS(RODRIGO!$N$2:$N$2,RODRIGO!$H$2:$H$2,"SALIDA",RODRIGO!$J$2:$J$2,$B33),0) -> 0 | J33: =IFERROR(SUMIFS(MOY!$N$2:$N$12,MOY!$H$2:$H$12,"SALIDA",MOY!$J$2:$J$12,$B33),0) -> 0 | K33: =IFERROR(SUMIFS('NORMA RUTH'!$N$2:$N$12,'NORMA RUTH'!$H$2:$H$12,"SALIDA",'NORMA RUTH'!$J$2:$J$12,$B33),0) -> 0 | L33: =IFERROR(SUMIFS(VALERIA!$N$2:$N$10,VALERIA!$H$2:$H$10,"SALIDA",VALERIA!$J$2:$J$10,$B33),0) -> 0 | M33: =IFERROR(SUMIFS('MANUEL BANAMEX'!$N$2:$N$25,'MANUEL BANAMEX'!$H$2:$H$25,"SALIDA",'MANUEL BANAMEX'!$J$2:$J$25,$B33),0) -> 0 | N33: =IFERROR(SUMIFS(ROBERTO!$N$2:$N$2,ROBERTO!$H$2:$H$2,"SALIDA",ROBERTO!$J$2:$J$2,$B33),0) -> 0 | O33: =IFERROR(SUMIFS(JUAN!$N$2:$N$11,JUAN!$H$2:$H$11,"SALIDA",JUAN!$J$2:$J$11,$B33),0) -> 0 | P33: =IFERROR(SUMIFS('NORMA SANCHEZ'!$N$2:$N$14,'NORMA SANCHEZ'!$H$2:$H$14,"SALIDA",'NORMA SANCHEZ'!$J$2:$J$14,$B33),0) -> 0 | Q33: =IFERROR(SUMIFS('JOSE CARLOS'!$N$2:$N$16,'JOSE CARLOS'!$H$2:$H$16,"SALIDA",'JOSE CARLOS'!$J$2:$J$16,$B33),0) -> 0 | R33: =IFERROR(SUMIFS('LUIS ENRIQUE '!$N$2:$N$21,'LUIS ENRIQUE '!$H$2:$H$21,"SALIDA",'LUIS ENRIQUE '!$J$2:$J$21,$B33),0) -> 0 | S33: =IFERROR(SUMIFS(CESARIA!$N$2:$N$15,CESARIA!$H$2:$H$15,"SALIDA",CESARIA!$J$2:$J$15,$B33),0) -> 0 | T33: =IFERROR(SUMIFS(ALAN!$N$2:$N$14,ALAN!$H$2:$H$14,"SALIDA",ALAN!$J$2:$J$14,$B33),0) -> 0 | U33: =IFERROR(SUMIFS(ELVIA!$N$2:$N$6,ELVIA!$H$2:$H$6,"SALIDA",ELVIA!$J$2:$J$6,$B33),0) -> 0 | V33: =IFERROR(SUMIFS(CAJA!$N$2:$N$586,CAJA!$H$2:$H$586,"SALIDA",CAJA!$J$2:$J$586,$B33),0) -> 11311 | W33: =IFERROR(SUMIFS('CAJA TIGRES'!$N$2:$N$139,'CAJA TIGRES'!$H$2:$H$139,"SALIDA",'CAJA TIGRES'!$J$2:$J$139,$B33),0) -> 2695 | X33: =IFERROR(SUMIFS(RESERVA!$N$2:$N$2,RESERVA!$H$2:$H$2,"SALIDA",RESERVA!$J$2:$J$2,$B33),0) -> 0 | Y33: =SUM(C33:X33) -> 31926 | Z33: =Y33 -> 31926
